Workbook

Sheet CongViec
A1: BẢNG KINH PHÍ CÔNG VIỆC (WORK COST BREAKDOWN) — DỰ ÁN XÂY DỰNG HỆ THỐNG HRMS CHO SME
A2: Mã số đề tài: VB2-CNTT-K69(1)-N02 | Nhóm 02 - Lớp B2CQ-CNTT-K69(01), Viện Đào tạo liên tục - Trường Công nghệ Thông tin và Truyền thông, Đại học Bách khoa Hà Nội
A3: Kinh phí công lao động theo các nhóm công việc chính của Bảng phân rã công việc (WBS). Định mức/ngày công tra tự động từ sheet CongLaoDong theo cột Người thực hiện.
A5: STT | B5: Các nội dung, công việc thực hiện | C5: Sản phẩm bàn giao | D5: Thời gian thực hiện | E5: Nhóm quy trình | F5: KINH PHÍ CÔNG LAO ĐỘNG
F6: Nhiệm vụ | G6: Người thực hiện | H6: Số ngày công | I6: Định mức (đ/ngày công) | J6: Thành tiền (đ)
A7: 1 | B7: A.1. Khởi tạo dự án và phê duyệt Project Charter | C7: Danh sách Sponsor và Ban Chỉ đạo; Tôn chỉ dự án; Sổ đăng ký các bên liên quan; Thuyết minh đề tài; Biên bản phê duyệt Project Charter | D7: 02/09/2026 - 11/09/2026 | E7: Khởi tạo | F7: Chủ nhiệm | G7: Trần Đức Cường | H7: 6.7 | I7: =VLOOKUP(G7,CongLaoDong!$B$8:$G$12,5,0) -> 1897500 | J7: =H7*I7 -> 12713250
F8: Thành viên | G8: Mai Công Trà Giang | H8: 1.2 | I8: =VLOOKUP(G8,CongLaoDong!$B$8:$G$12,5,0) -> 1391500 | J8: =H8*I8 -> 1669800
A9: 2 | B9: B.1. Lập kế hoạch quản trị lõi (Project Management Plan) | C9: Bảng phân rã công việc + Từ điển WBS; Bảng ước lượng PERT; Sơ đồ mạng và đường găng; Sơ đồ Gantt và danh mục cột mốc; Đường cơ sở chi phí và S-curve; Kế hoạch quản lý chất lượng; ... (tổng 12 sản phẩm, chi tiết tại WBS) | D9: 14/09/2026 - 08/10/2026 | E9: Lập kế hoạch | F9: Chủ nhiệm | G9: Trần Đức Cường | H9: 19.2 | I9: =VLOOKUP(G9,CongLaoDong!$B$8:$G$12,5,0) -> 1897500 | J9: =H9*I9 -> 36432000
F10: Thành viên | G10: Nguyễn Phương Thảo | H10: 1.6 | I10: =VLOOKUP(G10,CongLaoDong!$B$8:$G$12,5,0) -> 1391500 | J10: =H10*I10 -> 2226400
F11: Thành viên | G11: Mai Công Trà Giang | H11: 2.1 | I11: =VLOOKUP(G11,CongLaoDong!$B$8:$G$12,5,0) -> 1391500 | J11: =H11*I11 -> 2922150
A12: 3 | B12: B.2. Lập kế hoạch quản lý cấu hình và thay đổi | C12: Kế hoạch quản lý cấu hình; Kế hoạch quản lý thay đổi; Điều lệ CCB; Mẫu Yêu cầu thay đổi | D12: 05/10/2026 - 09/10/2026 | E12: Lập kế hoạch | F12: Chủ nhiệm | G12: Trần Đức Cường | H12: 4.2 | I12: =VLOOKUP(G12,CongLaoDong!$B$8:$G$12,5,0) -> 1897500 | J12: =H12*I12 -> 7969500
F13: Thành viên chính | G13: Bùi Tiến Thành | H13: 0.6 | I13: =VLOOKUP(G13,CongLaoDong!$B$8:$G$12,5,0) -> 1518000 | J13: =H13*I13 -> 910800
A14: 4 | B14: B.3. Chi tiết hóa kế hoạch các giai đoạn SDLC (Rolling Wave Planning) | C14: Kế hoạch phát triển phần mềm; Kế hoạch kiểm thử; Kế hoạch triển khai | D14: 08/10/2026 - 09/10/2026 | E14: Lập kế hoạch | F14: Thành viên chính | G14: Bùi Tiến Thành | H14: 2.2 | I14: =VLOOKUP(G14,CongLaoDong!$B$8:$G$12,5,0) -> 1518000 | J14: =H14*I14 -> 3339600
F15: Thành viên | G15: Nguyễn Phương Thảo | H15: 2.2 | I15: =VLOOKUP(G15,CongLaoDong!$B$8:$G$12,5,0) -> 1391500 | J15: =H15*I15 -> 3061300
F16: Thành viên | G16: Mai Công Trà Giang | H16: 2.2 | I16: =VLOOKUP(G16,CongLaoDong!$B$8:$G$12,5,0) -> 1391500 | J16: =H16*I16 -> 3061300
A17: 5 | B17: C.1. [SDLC-Scope] Khảo sát công nghệ và thiết lập môi trường | C17: Báo cáo khảo sát công nghệ; Báo cáo lựa chọn công nghệ; Môi trường Development đã cấu hình; Môi trường Staging đã cấu hình; Môi trường Production đã cấu hình; Bộ công cụ QLDA đã cấu hình; ... (tổng 8 sản phẩm, chi tiết tại WBS) | D17: 12/10/2026 - 24/10/2026 | E17: Thực hiện | F17: Chủ nhiệm | G17: Trần Đức Cường | H17: 2.6 | I17: =VLOOKUP(G17,CongLaoDong!$B$8:$G$12,5,0) -> 1897500 | J17: =H17*I17 -> 4933500
F18: Thành viên chính | G18: Lê Xuân Bách | H18: 4.4 | I18: =VLOOKUP(G18,CongLaoDong!$B$8:$G$12,5,0) -> 1518000 | J18: =H18*I18 -> 6679200
F19: Thành viên chính | G19: Bùi Tiến Thành | H19: 7.9 | I19: =VLOOKUP(G19,CongLaoDong!$B$8:$G$12,5,0) -> 1518000 | J19: =H19*I19 -> 11992200
A20: 6 | B20: C.2. [SDLC-Analysis] Khảo sát hiện trạng As-Is | C20: Bộ câu hỏi phỏng vấn; Biên bản phỏng vấn nhóm HR (ẩn danh); Biên bản phỏng vấn nhóm Manager (ẩn danh); Biên bản phỏng vấn nhóm Employee (ẩn danh); Nhật ký quan sát nghiệp vụ; ... (tổng 9 sản phẩm, chi tiết tại WBS) | D20: 26/10/2026 - 14/11/2026 | E20: Thực hiện | F20: Thành viên | G20: Nguyễn Phương Thảo | H20: 5.7 | I20: =VLOOKUP(G20,CongLaoDong!$B$8:$G$12,5,0) -> 1391500 | J20: =H20*I20 -> 7931550
F21: Thành viên | G21: Mai Công Trà Giang | H21: 14.2 | I21: =VLOOKUP(G21,CongLaoDong!$B$8:$G$12,5,0) -> 1391500 | J21: =H21*I21 -> 19759300
A22: 7 | B22: C.3. [SDLC-Analysis] Đặc tả yêu cầu (SRS) và mô hình To-Be | C22: Bộ biểu mẫu nghiệp vụ chuẩn hóa; Đặc tả FR M0 (Đăng nhập & phân quyền); Đặc tả FR M1 (Nhân sự & hợp đồng); Đặc tả FR M2 (Ca làm việc & chấm công); Đặc tả yêu cầu phi chức năng; Mô hình BPMN To-Be; ... (tổng 9 sản phẩm, chi tiết tại WBS) | D22: 16/11/2026 - 04/12/2026 | E22: Thực hiện | F22: Chủ nhiệm | G22: Trần Đức Cường | H22: 1.1 | I22: =VLOOKUP(G22,CongLaoDong!$B$8:$G$12,5,0) -> 1897500 | J22: =H22*I22 -> 2087250
F23: Thành viên | G23: Nguyễn Phương Thảo | H23: 18.8 | I23: =VLOOKUP(G23,CongLaoDong!$B$8:$G$12,5,0) -> 1391500 | J23: =H23*I23 -> 26160200
F24: Thành viên | G24: Mai Công Trà Giang | H24: 1.2 | I24: =VLOOKUP(G24,CongLaoDong!$B$8:$G$12,5,0) -> 1391500 | J24: =H24*I24 -> 1669800
A25: 8 | B25: C.4. [SDLC-Design] Phân tích và thiết kế hệ thống | C25: Biểu đồ Use Case tổng quát; Đặc tả Use Case chi tiết; Biểu đồ Lớp; Biểu đồ Tuần tự; Biểu đồ Hoạt động; Biểu đồ Thành phần; Biểu đồ Triển khai; Mô hình ERD + Từ điển dữ liệu; Bản thiết kế kiến trúc; ... (tổng 14 sản phẩm, chi tiết tại WBS) | D25: 07/12/2026 - 25/12/2026 | E25: Thực hiện | F25: Chủ nhiệm | G25: Trần Đức Cường | H25: 1.2 | I25: =VLOOKUP(G25,CongLaoDong!$B$8:$G$12,5,0) -> 1897500 | J25: =H25*I25 -> 2277000
F26: Thành viên chính | G26: Lê Xuân Bách | H26: 15.5 | I26: =VLOOKUP(G26,CongLaoDong!$B$8:$G$12,5,0) -> 1518000 | J26: =H26*I26 -> 23529000
F27: Thành viên chính | G27: Bùi Tiến Thành | H27: 6.2 | I27: =VLOOKUP(G27,CongLaoDong!$B$8:$G$12,5,0) -> 1518000 | J27: =H27*I27 -> 9411600
F28: Thành viên | G28: Nguyễn Phương Thảo | H28: 3 | I28: =VLOOKUP(G28,CongLaoDong!$B$8:$G$12,5,0) -> 1391500 | J28: =H28*I28 -> 4174500
F29: Thành viên | G29: Mai Công Trà Giang | H29: 10.7 | I29: =VLOOKUP(G29,CongLaoDong!$B$8:$G$12,5,0) -> 1391500 | J29: =H29*I29 -> 14889050
A30: 9 | B30: C.5. [SDLC-Development] Phát triển phần mềm (Incremental 3 increment) | C30: Mã nguồn Backend M0 + API docs; Mã nguồn Frontend M0; Bộ unit test M0 + báo cáo code review; Bản build M0 trên Staging + Biên bản demo; Mã nguồn Backend M1 + API docs; Mã nguồn Frontend M1; ... (tổng 17 sản phẩm, chi tiết tại WBS) | D30: 28/12/2026 - 29/01/2027 | E30: Thực hiện | F30: Chủ nhiệm | G30: Trần Đức Cường | H30: 1 | I30: =VLOOKUP(G30,CongLaoDong!$B$8:$G$12,5,0) -> 1897500 | J30: =H30*I30 -> 1897500
F31: Thành viên chính | G31: Lê Xuân Bách | H31: 22.8 | I31: =VLOOKUP(G31,CongLaoDong!$B$8:$G$12,5,0) -> 1518000 | J31: =H31*I31 -> 34610400
F32: Thành viên chính | G32: Bùi Tiến Thành | H32: 24.8 | I32: =VLOOKUP(G32,CongLaoDong!$B$8:$G$12,5,0) -> 1518000 | J32: =H32*I32 -> 37646400
F33: Thành viên | G33: Nguyễn Phương Thảo | H33: 8.6 | I33: =VLOOKUP(G33,CongLaoDong!$B$8:$G$12,5,0) -> 1391500 | J33: =H33*I33 -> 11966900
F34: Thành viên | G34: Mai Công Trà Giang | H34: 3.2 | I34: =VLOOKUP(G34,CongLaoDong!$B$8:$G$12,5,0) -> 1391500 | J34: =H34*I34 -> 4452800
A35: 10 | B35: C.6. [SDLC-Testing] Kiểm thử hệ thống (System Test) | C35: Bộ kịch bản kiểm thử hệ thống; Báo cáo kiểm thử chức năng; Báo cáo kiểm thử hiệu năng; Báo cáo kiểm thử bảo mật; Báo cáo regression test; Bản build đã fix defect + Verify log; ... (tổng 7 sản phẩm, chi tiết tại WBS) | D35: 25/01/2027 - 07/02/2027 | E35: Thực hiện | F35: Thành viên chính | G35: Lê Xuân Bách | H35: 3.5 | I35: =VLOOKUP(G35,CongLaoDong!$B$8:$G$12,5,0) -> 1518000 | J35: =H35*I35 -> 5313000
F36: Thành viên chính | G36: Bùi Tiến Thành | H36: 7.9 | I36: =VLOOKUP(G36,CongLaoDong!$B$8:$G$12,5,0) -> 1518000 | J36: =H36*I36 -> 11992200
F37: Thành viên | G37: Nguyễn Phương Thảo | H37: 5.1 | I37: =VLOOKUP(G37,CongLaoDong!$B$8:$G$12,5,0) -> 1391500 | J37: =H37*I37 -> 7096650
A38: 11 | B38: C.7. [SDLC-Testing] Kiểm thử chấp nhận (User Acceptance Test) | C38: Kịch bản UAT đã ký thống nhất; Biên bản onboarding UAT + Tài liệu hướng dẫn; Nhật ký hỗ trợ UAT; Defect Log UAT + Bản build đã fix; Biên bản UAT có ký của khách hàng; Biên bản phê duyệt UAT | D38: 05/02/2027 - 12/02/2027 | E38: Thực hiện | F38: Chủ nhiệm | G38: Trần Đức Cường | H38: 1 | I38: =VLOOKUP(G38,CongLaoDong!$B$8:$G$12,5,0) -> 1897500 | J38: =H38*I38 -> 1897500
F39: Thành viên chính | G39: Lê Xuân Bách | H39: 3.5 | I39: =VLOOKUP(G39,CongLaoDong!$B$8:$G$12,5,0) -> 1518000 | J39: =H39*I39 -> 5313000
F40: Thành viên | G40: Nguyễn Phương Thảo | H40: 1.1 | I40: =VLOOKUP(G40,CongLaoDong!$B$8:$G$12,5,0) -> 1391500 | J40: =H40*I40 -> 1530650
F41: Thành viên | G41: Mai Công Trà Giang | H41: 6.7 | I41: =VLOOKUP(G41,CongLaoDong!$B$8:$G$12,5,0) -> 1391500 | J41: =H41*I41 -> 9323050
...

Sheet CongLaoDong
A1: PHỤ LỤC DỰ TOÁN KINH PHÍ 1. CÔNG LAO ĐỘNG KHOA HỌC (KHOÁN CHI)
A2: ĐỀ TÀI | B2: XÂY DỰNG HỆ THỐNG QUẢN TRỊ NHÂN SỰ (HRMS) CHO DOANH NGHIỆP VỪA VÀ NHỎ (SME)
A3: MÃ SỐ | B3: VB2-CNTT-K69(1)-N02
A4: CHỦ TRÌ | B4: Trần Đức Cường
A5: Mức khoán ngày công cơ sở (đồng/ngày công chuẩn): | E5: 2530000
A7: TT | B7: Họ và tên | C7: Nhiệm vụ trong dự án | D7: Số ngày công | E7: Hệ số nhiệm vụ | F7: Định mức (đ/ngày công) | G7: Thành tiền (đ) | H7: Tỷ trọng
A8: 1 | B8: Trần Đức Cường | C8: Chủ nhiệm dự án (Giám đốc dự án) | D8: =SUMIF(CongViec!$G:$G,$B8,CongViec!$H:$H) -> 57.6 | E8: 0.75 | F8: =E8*$E$5 -> 1897500 | G8: =D8*F8 -> 109296000 | H8: =IF($G$13=0,0,G8/$G$13) -> 0.2439782
A9: 2 | B9: Lê Xuân Bách | C9: Thành viên chính (Kiến trúc sư trưởng) | D9: =SUMIF(CongViec!$G:$G,$B9,CongViec!$H:$H) -> 57.8 | E9: 0.6 | F9: =E9*$E$5 -> 1518000 | G9: =D9*F9 -> 87740400 | H9: =IF($G$13=0,0,G9/$G$13) -> 0.19586028
A10: 3 | B10: Bùi Tiến Thành | C10: Thành viên chính (DevOps & Test Lead) | D10: =SUMIF(CongViec!$G:$G,$B10,CongViec!$H:$H) -> 58.7 | E10: 0.6 | F10: =E10*$E$5 -> 1518000 | G10: =D10*F10 -> 89106600 | H10: =IF($G$13=0,0,G10/$G$13) -> 0.19891
A11: 4 | B11: Nguyễn Phương Thảo | C11: Thành viên (Phân tích nghiệp vụ - SRS) | D11: =SUMIF(CongViec!$G:$G,$B11,CongViec!$H:$H) -> 58.1 | E11: 0.55 | F11: =E11*$E$5 -> 1391500 | G11: =D11*F11 -> 80846150 | H11: =IF($G$13=0,0,G11/$G$13) -> 0.18047045
A12: 5 | B12: Mai Công Trà Giang | C12: Thành viên (Phân tích nghiệp vụ - Khảo sát) | D12: =SUMIF(CongViec!$G:$G,$B12,CongViec!$H:$H) -> 58.2 | E12: 0.55 | F12: =E12*$E$5 -> 1391500 | G12: =D12*F12 -> 80985300 | H12: =IF($G$13=0,0,G12/$G$13) -> 0.18078107
A13: TỔNG CỘNG | D13: =SUM(D8:D12) -> 290.4 | F13: =IF(D13=0,0,G13/D13) -> 1542611.7 | G13: =SUM(G8:G12) -> 447974450 | H13: =IF($G$13=0,0,G13/$G$13) -> 1
A14: Bằng chữ: Bốn trăm bốn mươi bảy triệu chín trăm bảy mươi tư nghìn bốn trăm năm mươi đồng.
A15: ĐỐI CHIẾU
B16: =CongViec!H64 -> 290.4 | C16: Tổng ngày công theo WBS (EST chốt)
B17: =D13-B16 -> 0 | C17: Chênh lệch ngày công so với WBS (phải bằng 0)
B18: =CongViec!J64 -> 447974450 | C18: Tổng thành tiền theo sheet CongViec
B19: =G13-B18 -> 0 | C19: Chênh lệch thành tiền so với sheet CongViec (phải bằng 0)
A21: CHÚ THÍCH
A22: • Số ngày công | C22: Tự động cộng dồn từ sheet CongViec theo cột "Người thực hiện" (hàm SUMIF), truy vết trực tiếp về WBS.
A23: • Hệ số nhiệm vụ | C23: Phân theo vai trò trong Tôn chỉ dự án: Chủ nhiệm 0,75; Thành viên chính 0,60; Thành viên 0,55. Đây là ô nhập liệu, sửa được.
A24: • Định mức/ngày công | C24: Công thức: Hệ số nhiệm vụ × Mức khoán ngày công cơ sở (ô E5 = 2.530.000 đ/ngày công chuẩn, do nhóm ấn định).
A25: • Trần tải nguồn lực | C25: 60 person-day/người theo WBS; số ngày công của mỗi thành viên không vượt trần này.
E27: Hà Nội, ngày ..... tháng ..... năm 2026
B28: CHỦ NHIỆM DỰ ÁN | E28: NGƯỜI LẬP BẢNG
B31: Trần Đức Cường | E31: Trần Đức Cường

Sheet Dự toán
A1: BẢNG DỰ TOÁN KINH PHÍ
A2: ĐỀ TÀI | B2: XÂY DỰNG HỆ THỐNG QUẢN TRỊ NHÂN SỰ (HRMS) CHO DOANH NGHIỆP VỪA VÀ NHỎ (SME)
A3: MÃ SỐ | B3: VB2-CNTT-K69(1)-N02
A4: CHỦ TRÌ | B4: Trần Đức Cường
A5: THỜI GIAN | B5: 06 tháng, từ 01/09/2026 đến 28/02/2027
A7: TT | B7: Danh mục | C7: Số tiền (đ) | D7: Ghi chú
A8: 1 | B8: Công lao động khoa học (thuê khoán chuyên môn) | C8: =CongLaoDong!G13 -> 447974450 | D8: Chi tiết tại sheet CongLaoDong và CongViec; tổng hợp từ 137 gói công việc của WBS.
A9: 2 | B9: Vật tư, thiết bị (hạ tầng cloud + license công cụ) | C9: ='Thiết bị vật tư'!F21 -> 46000000 | D9: Chi tiết tại sheet Thiết bị vật tư; phân bổ theo 03 giai đoạn triển khai.
A10: 3 | B10: Chi khác (khảo sát, hội họp, VPP, quản lý, dự phòng) | C10: ='Chi khác'!D25 -> 146025550 | D10: Chi tiết tại sheet Chi khác; gồm chi phí quản lý 5% và khoản dự phòng tự cân đối.
A11: TỔNG CỘNG | C11: =SUM(C8:C10) -> 640000000 | D11: Bằng chữ: Sáu trăm bốn mươi triệu đồng chẵn.
A13: ĐỐI CHIẾU VỚI TÔN CHỈ DỰ ÁN (COST BASELINE)
A14: TT | B14: Chỉ tiêu | C14: Giá trị (đ) | D14: Ghi chú
A15: 1 | B15: Tổng kinh phí được duyệt theo Tôn chỉ dự án | C15: ='Chi khác'!$D$5 -> 640000000 | D15: Ô nhập liệu gốc đặt tại sheet Chi khác, ô D5.
A16: 2 | B16: Chênh lệch Tổng dự toán − Tổng được duyệt | C16: =C11-C15 -> 0 | D16: Phải bằng 0; dòng Dự phòng tại sheet Chi khác tự cân đối.
A17: 3 | B17: Chỉ tiêu thuê khoán chuyên môn (70% tổng kinh phí) | C17: 448000000 | D17: Giữ đúng tỷ trọng 70% tổng kinh phí theo Tôn chỉ dự án (70% × 640.000.000 đ).
A18: 4 | B18: Chênh lệch Công lao động so với chỉ tiêu | C18: =C8-C17 -> -25550 | D18: Phần chênh được điều chỉnh vào khoản Dự phòng của sheet Chi khác.
A19: 5 | B19: Tỷ lệ sai lệch Công lao động | C19: =IF(C17=0,0,C18/C17) -> -5.703125e-05 | D19: Ngưỡng kiểm soát theo Tôn chỉ dự án: không vượt quá ±10%.
C21: Hà Nội, ngày ..... tháng ..... năm 2026
C22: CHỦ NHIỆM DỰ ÁN
C25: Trần Đức Cường

Sheet Thiết bị vật tư
A1: PHỤ LỤC DỰ TOÁN KINH PHÍ 2. VẬT TƯ, THIẾT BỊ (HẠ TẦNG CLOUD VÀ LICENSE CÔNG CỤ)
A2: ĐỀ TÀI | B2: XÂY DỰNG HỆ THỐNG QUẢN TRỊ NHÂN SỰ (HRMS) CHO DOANH NGHIỆP VỪA VÀ NHỎ (SME)
A3: MÃ SỐ | B3: VB2-CNTT-K69(1)-N02
A4: CHỦ TRÌ | B4: Trần Đức Cường
A5: Vật tư, thiết bị phục vụ đề tài - phân bổ theo 03 giai đoạn triển khai
A7: TT | B7: TÊN VẬT TƯ, THIẾT BỊ, DỊCH VỤ | C7: ĐƠN VỊ TÍNH | D7: SỐ LƯỢNG | E7: ĐƠN GIÁ (đ) | F7: THÀNH TIỀN (đ) | G7: Ghi chú
A8: I | B8: Giai đoạn 1 - Thiết lập môi trường và công cụ (T9-T10/2026)
A9: 1 | B9: Thuê hạ tầng cloud môi trường Development | C9: tháng | D9: 5 | E9: 1000000 | F9: =D9*E9 -> 5000000 | G9: VPS/container cho nhóm phát triển, từ T10/2026 đến T02/2027
A10: 2 | B10: Thuê hạ tầng cloud môi trường Staging | C10: tháng | D10: 5 | E10: 1300000 | F10: =D10*E10 -> 6500000 | G10: Môi trường kiểm thử tích hợp, cấu hình gần giống Production
A11: 3 | B11: License bộ công cụ QLDA (Jira/Confluence) | C11: user-tháng | D11: 30 | E11: 200000 | F11: =D11*E11 -> 6000000 | G11: 05 thành viên × 06 tháng
A12: 4 | B12: License công cụ thiết kế giao diện (Figma) | C12: user-tháng | D12: 8 | E12: 375000 | F12: =D12*E12 -> 3000000 | G12: 02 thành viên × 04 tháng, phục vụ wireframe - mockup - prototype
A13: II | B13: Giai đoạn 2 - Phát triển và kiểm thử (T11/2026-T01/2027)
A14: 1 | B14: License công cụ phân tích tĩnh mã nguồn (SonarQube) | C14: gói | D14: 1 | E14: 4000000 | F14: =D14*E14 -> 4000000 | G14: Phục vụ công việc "Phân tích tĩnh mã nguồn" của WBS
A15: 2 | B15: License công cụ kiểm thử hiệu năng và bảo mật | C15: gói | D15: 1 | E15: 4000000 | F15: =D15*E15 -> 4000000 | G15: Phục vụ kiểm thử Load/Stress và quét OWASP Top 10
A16: III | B16: Giai đoạn 3 - Triển khai và vận hành (T12/2026-T02/2027)
A17: 1 | B17: Thuê hạ tầng cloud môi trường Production | C17: tháng | D17: 3 | E17: 3000000 | F17: =D17*E17 -> 9000000 | G17: Đã gồm dung lượng lưu trữ và băng thông phục vụ go-live; từ T12/2026 đến T02/2027
A18: 2 | B18: Dịch vụ sao lưu và giám sát hệ thống | C18: tháng | D18: 3 | E18: 800000 | F18: =D18*E18 -> 2400000 | G18: Backup định kỳ và monitoring theo Configuration Management Plan; từ T12/2026 đến T02/2027
A19: 3 | B19: Chứng thư số SSL cho môi trường Production | C19: chứng thư | D19: 1 | E19: 1600000 | F19: =D19*E19 -> 1600000 | G19: Yêu cầu bảo mật theo đặc tả phi chức năng (NFR)
A20: 4 | B20: Thiết bị, phụ kiện tích hợp máy chấm công | C20: bộ | D20: 1 | E20: 4500000 | F20: =D20*E20 -> 4500000 | G20: Phục vụ tích hợp máy chấm công (T01/2027); chỉ mua sau khi kiểm chứng khả năng kết nối (R13)
A21: TỔNG CỘNG | F21: =SUM(F8:F20) -> 46000000 | G21: Bằng chữ: Bốn mươi sáu triệu đồng chẵn.
A23: CHÚ THÍCH
A24: • Cơ sở lập dự toán | C24: Chỉ tiêu "Hạ tầng cloud + license công cụ" 46.000.000 đ, giữ tỷ trọng 7,2% tổng kinh phí như Tôn chỉ dự án.
A25: • Nguyên tắc | C25: Thuê dịch vụ theo thời gian sử dụng thực tế, không mua sắm tài sản cố định.
E27: Hà Nội, ngày ..... tháng ..... năm 2026
B28: CHỦ NHIỆM DỰ ÁN | E28: NGƯỜI LẬP BẢNG
B31: Trần Đức Cường | E31: Trần Đức Cường

Sheet Chi khác
A1: PHỤ LỤC DỰ TOÁN KINH PHÍ 3. CHI KHÁC (KHẢO SÁT, HỘI HỌP, VĂN PHÒNG PHẨM, QUẢN LÝ, DỰ PHÒNG)
A2: ĐỀ TÀI | B2: XÂY DỰNG HỆ THỐNG QUẢN TRỊ NHÂN SỰ (HRMS) CHO DOANH NGHIỆP VỪA VÀ NHỎ (SME)
A3: MÃ SỐ | B3: VB2-CNTT-K69(1)-N02
A4: CHỦ TRÌ | B4: Trần Đức Cường
A5: Tổng kinh phí được duyệt theo Tôn chỉ dự án (đồng): | D5: 640000000
A7: TT | B7: NỘI DUNG | C7: Mô tả chi tiết | D7: SỐ TIỀN (đ)
A8: I | B8: Khảo sát và đi lại
A9: 1 | B9: Đi lại khảo sát hiện trạng As-Is tại doanh nghiệp | C9: 12 lượt × 650.000 đ - phỏng vấn 03 nhóm HR/Manager/Employee và quan sát chu kỳ chốt công | D9: 7800000
A10: 2 | B10: Đi lại hỗ trợ UAT và đào tạo người dùng | C10: 10 lượt × 650.000 đ - onboarding UAT, hỗ trợ on-site, đào tạo super users và người dùng cuối | D10: 6500000
A11: 3 | B11: Đi lại hỗ trợ hyper-care sau go-live | C11: 10 lượt × 650.000 đ - hỗ trợ tại chỗ trong 02 tuần đầu sau go-live M2 | D11: 6500000
A12: 4 | B12: Công tác phí khảo sát chu kỳ chốt công | C12: Tham dự trọn 01 chu kỳ chấm công - chốt công tại doanh nghiệp | D12: 5200000
A13: II | B13: Hội họp, đào tạo, demo
A14: 1 | B14: Workshop xác nhận SRS với khách hàng | C14: 01 buổi workshop xác nhận và ký nháp SRS v1.0 (cột mốc M3) | D14: 4000000
A15: 2 | B15: Hội nghị đào tạo super users và người dùng cuối | C15: Đào tạo super users 02 ngày và đào tạo người dùng cuối theo mô hình Train-the-Trainer | D15: 6500000
A16: 3 | B16: Tổ chức demo sau mỗi increment và demo UAT | C16: 04 phiên: M0 (07/01), M1 (18/01), M2 (28/01) và demo UAT (12/02/2027) | D16: 3500000
A17: 4 | B17: Họp Ban Chỉ đạo, họp CCB và nghiệm thu | C17: Họp phê duyệt các cột mốc M1-M8, họp CCB (dự kiến 5-8 phiên) và nghiệm thu tổng thể | D17: 4000000
A18: III | B18: In ấn, tài liệu, văn phòng phẩm
A19: 1 | B19: In ấn, đóng quyển hồ sơ quản trị dự án | C19: 06 bộ hồ sơ: Thuyết minh và Tôn chỉ dự án; bộ tài liệu QLDA; As-Is và SRS; khảo sát công nghệ; phân tích - thiết kế; báo cáo tổng hợp | D19: 5000000
A20: 2 | B20: In tài liệu đào tạo, User Guide, Admin Guide | C20: Tài liệu đào tạo cho 03 vai trò, User Guide, Admin Guide và Operation Runbook | D20: 4000000
A21: 3 | B21: Văn phòng phẩm phục vụ khảo sát, họp, nghiệm thu | C21: Phô tô biểu mẫu, bảng hỏi phỏng vấn, biên bản họp và biên bản nghiệm thu trong toàn dự án | D21: 4000000
A22: IV | B22: Chi phí quản lý và dự phòng
A23: 1 | B23: Chi phí quản lý dự án | C23: 5% tổng kinh phí được duyệt (= 5% × 640.000.000 đ) theo Tôn chỉ dự án | D23: =ROUND($D$5*5%,0) -> 32000000
A24: 2 | B24: Dự phòng | C24: Tự cân đối: Tổng kinh phí được duyệt trừ Công lao động, Vật tư thiết bị và các khoản Chi khác đã liệt kê | D24: =$D$5-CongLaoDong!$G$13-'Thiết bị vật tư'!$F$21-(D9+D10+D11+D12+D14+D15+D16+D17+D19+D20+D21+D23) -> 57025550
A25: TỔNG CỘNG | D25: =SUM(D9,D10,D11,D12,D14,D15,D16,D17,D19,D20,D21,D23,D24) -> 146025550
A26: Bằng chữ: Một trăm bốn mươi sáu triệu không trăm hai mươi lăm nghìn năm trăm năm mươi đồng.
A27: CHÚ THÍCH
A28: • Cơ sở lập dự toán | C28: Khảo sát và đi lại 26.000.000 đ; Hội họp, đào tạo, demo 18.000.000 đ; In ấn, tài liệu, VPP 13.000.000 đ; Chi phí quản lý 5% = 32.000.000 đ; phần còn lại là Dự phòng. Cơ cấu giữ đúng tỷ trọng của Tôn chỉ dự án.
A29: • Dòng Dự phòng | C29: Là công thức tự cân đối để Tổng dự toán luôn bằng Tổng kinh phí được duyệt (ô D5); khi điều chỉnh bất kỳ khoản mục nào, Dự phòng thay đổi tương ứng.
C31: Hà Nội, ngày ..... tháng ..... năm 2026
A32: CHỦ NHIỆM DỰ ÁN | C32: NGƯỜI LẬP BẢNG
A35: Trần Đức Cường | C35: Trần Đức Cường

Sheet KeHoachThanhToan
A1: PHỤ LỤC DỰ TOÁN KINH PHÍ 4. KẾ HOẠCH THANH TOÁN VÀ DÒNG TIỀN DỰ ÁN
A2: ĐỀ TÀI | B2: XÂY DỰNG HỆ THỐNG QUẢN TRỊ NHÂN SỰ (HRMS) CHO DOANH NGHIỆP VỪA VÀ NHỎ (SME)
A3: MÃ SỐ | B3: VB2-CNTT-K69(1)-N02
A4: CHỦ TRÌ | B4: Trần Đức Cường
A5: Giá trị hợp đồng với Chủ đầu tư (đồng): | D5: ='Chi khác'!$D$5 -> 640000000 | E5: Liên kết từ sheet Chi khác (Tổng kinh phí được duyệt theo Tôn chỉ dự án). Hợp đồng trọn gói, thanh toán theo cột mốc nghiệm thu.
A6: Số ngày làm việc từ khi nghiệm thu đến khi nhận tiền: | D6: 7 | E6: Theo điều khoản thanh toán đề xuất trong hợp đồng: Chủ đầu tư thanh toán trong 07 ngày làm việc kể từ khi nhận đủ hồ sơ hợp lệ.
A8: I. KẾ HOẠCH THANH TOÁN THEO CỘT MỐC NGHIỆM THU
A9: TT | B9: Đợt thanh toán | C9: Cột mốc nghiệm thu | D9: Ngày cột mốc | E9: Điều kiện thanh toán (hồ sơ kèm theo) | F9: Tỷ lệ (%) | G9: Số tiền (đ) | H9: Ngày nhận tiền dự kiến | I9: Lũy kế thu (đ) | J9: Ghi chú
A10: 1 | B10: Đợt 1 - Tạm ứng | C10: M1 - Phê duyệt Project Charter | D10: 46276 | E10: Hợp đồng đã ký; Biên bản phê duyệt Project Charter; đề nghị tạm ứng | F10: 0.2 | G10: =ROUND($D$5*F10,0) -> 128000000 | H10: =WORKDAY(D10,$D$6) -> 46287 | I10: =SUM($G$10:G10) -> 128000000 | J10: Khởi động dự án, chi trả giai đoạn Khởi tạo - Lập kế hoạch
A11: 2 | B11: Đợt 2 | C11: M2 - Phê duyệt các baseline | D11: 46304 | E11: Kế hoạch quản trị dự án tổng thể được Ban Chỉ đạo phê duyệt; biên bản nghiệm thu cột mốc | F11: 0.15 | G11: =ROUND($D$5*F11,0) -> 96000000 | H11: =WORKDAY(D11,$D$6) -> 46315 | I11: =SUM($G$10:G11) -> 224000000 | J11: Bù chi giai đoạn Khảo sát công nghệ, khảo sát As-Is
A12: 3 | B12: Đợt 3 | C12: M3 - Ký xác nhận SRS | D12: 46360 | E12: SRS v1.0 và RTM có chữ ký xác nhận của Chủ đầu tư | F12: 0.15 | G12: =ROUND($D$5*F12,0) -> 96000000 | H12: =WORKDAY(D12,$D$6) -> 46371 | I12: =SUM($G$10:G12) -> 320000000 | J12: Bù chi giai đoạn Phân tích - Thiết kế
A13: 4 | B13: Đợt 4 | C13: M4 - Nghiệm thu thiết kế | D13: 46381 | E13: Báo cáo phân tích - thiết kế hệ thống được nghiệm thu | F13: 0.25 | G13: =ROUND($D$5*F13,0) -> 160000000 | H13: =WORKDAY(D13,$D$6) -> 46392 | I13: =SUM($G$10:G13) -> 480000000 | J13: Đợt lớn nhất, đón trước giai đoạn Phát triển (chi cao nhất)
A14: 5 | B14: Đợt 5 | C14: M6 - UAT đạt | D14: 46430 | E14: Biên bản UAT có chữ ký khách hàng; Biên bản phê duyệt UAT | F14: 0.2 | G14: =ROUND($D$5*F14,0) -> 128000000 | H14: =WORKDAY(D14,$D$6) -> 46441 | I14: =SUM($G$10:G14) -> 608000000 | J14: Bù chi giai đoạn Kiểm thử - Triển khai
A15: 6 | B15: Đợt 6 - Quyết toán | C15: M8 - Nghiệm thu chính thức | D15: 46444 | E15: Biên bản nghiệm thu chính thức (M8); hồ sơ quyết toán; biên bản đóng hợp đồng | F15: 0.05 | G15: =ROUND($D$5*F15,0) -> 32000000 | H15: =WORKDAY(D15,$D$6) -> 46455 | I15: =SUM($G$10:G15) -> 640000000 | J15: Khoản giữ lại đến khi quyết toán
A16: TỔNG CỘNG | F16: =SUM(F10:F15) -> 1 | G16: =SUM(G10:G15) -> 640000000 | J16: =IF(ROUND(F16,6)=1,"Đủ 100% giá trị hợp đồng","Tổng tỷ lệ phải bằng 100%") -> Đủ 100% giá trị hợp đồng
A18: II. DÒNG TIỀN DỰ KIẾN THEO THÁNG (CHI THEO COST BASELINE, THU THEO KẾ HOẠCH THANH TOÁN)
A19: Tháng | B19: Ngày cuối tháng | C19: Chi công lao động (đ) | D19: Chi vật tư, thiết bị (đ) | E19: Chi khác, không gồm dự phòng (đ) | F19: Tổng chi trong tháng (đ) | G19: Lũy kế chi (đ) | H19: Thu trong tháng (đ) | I19: Lũy kế thu (đ) | J19: Chênh lệch lũy kế thu - chi (đ)
A20: T09/2026 | B20: =EOMONTH(DATE(2026,9,1),0) -> 46295 | C20: 45360707 | D20: 1000000 | E20: 6666667 | F20: =SUM(C20:E20) -> 53027374 | G20: =SUM($F$20:F20) -> 53027374 | H20: =SUMIFS($G$10:$G$15,$H$10:$H$15,">"&EOMONTH(B20,-1),$H$10:$H$15,"<="&B20) -> 128000000 | I20: =SUM($H$20:H20) -> 128000000 | J20: =I20-G20 -> 74972626
A21: T10/2026 | B21: =EOMONTH(B20,1) -> 46326 | C21: 69979884 | D21: 4050000 | E21: 9006667 | F21: =SUM(C21:E21) -> 83036551 | G21: =SUM($F$20:F21) -> 136063925 | H21: =SUMIFS($G$10:$G$15,$H$10:$H$15,">"&EOMONTH(B21,-1),$H$10:$H$15,"<="&B21) -> 96000000 | I21: =SUM($H$20:H21) -> 224000000 | J21: =I21-G21 -> 87936075
A22: T11/2026 | B22: =EOMONTH(B21,1) -> 46356 | C22: 48240986 | D22: 4050000 | E22: 17326667 | F22: =SUM(C22:E22) -> 69617653 | G22: =SUM($F$20:F22) -> 205681578 | H22: =SUMIFS($G$10:$G$15,$H$10:$H$15,">"&EOMONTH(B22,-1),$H$10:$H$15,"<="&B22) -> 0 | I22: =SUM($H$20:H22) -> 224000000 | J22: =I22-G22 -> 18318422
A23: T12/2026 | B23: =EOMONTH(B22,1) -> 46387 | C23: 78835681 | D23: 11850000 | E23: 10666667 | F23: =SUM(C23:E23) -> 101352348 | G23: =SUM($F$20:F23) -> 307033926 | H23: =SUMIFS($G$10:$G$15,$H$10:$H$15,">"&EOMONTH(B23,-1),$H$10:$H$15,"<="&B23) -> 96000000 | I23: =SUM($H$20:H23) -> 320000000 | J23: =I23-G23 -> 12966074
A24: T01/2027 | B24: =EOMONTH(B23,1) -> 46418 | C24: 98538614 | D24: 16350000 | E24: 9291667 | F24: =SUM(C24:E24) -> 124180281 | G24: =SUM($F$20:F24) -> 431214207 | H24: =SUMIFS($G$10:$G$15,$H$10:$H$15,">"&EOMONTH(B24,-1),$H$10:$H$15,"<="&B24) -> 160000000 | I24: =SUM($H$20:H24) -> 480000000 | J24: =I24-G24 -> 48785793
A25: T02/2027 | B25: =EOMONTH(B24,1) -> 46446 | C25: 107018578 | D25: 8700000 | E25: 36041665 | F25: =SUM(C25:E25) -> 151760243 | G25: =SUM($F$20:F25) -> 582974450 | H25: =SUMIFS($G$10:$G$15,$H$10:$H$15,">"&EOMONTH(B25,-1),$H$10:$H$15,"<="&B25) -> 128000000 | I25: =SUM($H$20:H25) -> 608000000 | J25: =I25-G25 -> 25025550
A26: T03/2027 | B26: =EOMONTH(B25,1) -> 46477 | C26: 0 | D26: 0 | E26: 0 | F26: =SUM(C26:E26) -> 0 | G26: =SUM($F$20:F26) -> 582974450 | H26: =SUMIFS($G$10:$G$15,$H$10:$H$15,">"&EOMONTH(B26,-1),$H$10:$H$15,"<="&B26) -> 32000000 | I26: =SUM($H$20:H26) -> 640000000 | J26: =I26-G26 -> 57025550
A27: TỔNG CỘNG | C27: =SUM(C20:C26) -> 447974450 | D27: =SUM(D20:D26) -> 46000000 | E27: =SUM(E20:E26) -> 89000000 | F27: =SUM(F20:F26) -> 582974450 | G27: =G26 -> 582974450 | H27: =SUM(H20:H26) -> 640000000 | I27: =I26 -> 640000000 | J27: =J26 -> 57025550
A29: III. ĐỐI CHIẾU
A30: TT | B30: Chỉ tiêu | F30: Giá trị (đ) | G30: Ghi chú
A31: 1 | B31: Chênh lệch chi công lao động so với sheet CongLaoDong | F31: =C27-CongLaoDong!$G$13 -> 0 | G31: Phải bằng 0
A32: 2 | B32: Chênh lệch chi vật tư, thiết bị so với sheet Thiết bị vật tư | F32: =D27-'Thiết bị vật tư'!$F$21 -> 0 | G32: Phải bằng 0
A33: 3 | B33: Chênh lệch chi khác so với sheet Chi khác (không gồm dự phòng) | F33: =E27-('Chi khác'!$D$25-'Chi khác'!$D$24) -> 0 | G33: Phải bằng 0
A34: 4 | B34: Chênh lệch tổng thu so với giá trị hợp đồng | F34: =H27-$D$5 -> 0 | G34: Phải bằng 0
A35: 5 | B35: Chênh lệch lũy kế cuối dự án so với khoản Dự phòng | F35: =J26-'Chi khác'!$D$24 -> 0 | G35: Phải bằng 0: phần dư cuối dự án đúng bằng khoản dự phòng chưa sử dụng
A36: 6 | B36: Số tháng có chênh lệch lũy kế thu - chi âm | F36: =COUNTIF(J20:J26,"<0") -> 0 | G36: Phải bằng 0: dự án không thiếu hụt dòng tiền tại mọi thời điểm cuối tháng
A37: 7 | B37: Chênh lệch lũy kế thu - chi thấp nhất trong kỳ | F37: =MIN(J20:J26) -> 12966074 | G37: Biên an toàn dòng tiền; thấp nhất rơi vào tháng 12/2026
A39: CHÚ THÍCH
A40: • Ngày cột mốc | B40: Theo danh mục cột mốc M1-M8 tại Bảng phân rã công việc: M1 11/09/2026; M2 09/10/2026; M3 04/12/2026; M4 25/12/2026; M6 12/02/2027; M8 26/02/2027.
A41: • Ngày nhận tiền | B41: Công thức WORKDAY(Ngày cột mốc; ô D6), chỉ loại trừ thứ Bảy, Chủ nhật; chưa trừ ngày nghỉ lễ, Tết.
A42: • Thu trong tháng | B42: Công thức SUMIFS cộng các đợt có Ngày nhận tiền rơi vào tháng tương ứng.
A43: • Phân bổ chi theo tháng | B43: Công lao động của nhóm công việc có thời gian cụ thể (A, B, C, E tại sheet CongViec) được chia theo số ngày lịch rơi vào từng tháng; nhóm D (giám sát xuyên suốt) chia đều cho các tháng hoạt động. Vật tư, thiết bị và chi khác phân bổ theo thời điểm sử dụng ghi tại sheet Thiết bị vật tư và Chi khác. Số lẻ làm tròn được dồn vào tháng 02/2027.
A44: • Giả định dòng chi | B44: Chi phí được thanh toán vào cuối tháng phát sinh; khoản Dự phòng không đưa vào dòng chi kế hoạch và chỉ sử dụng khi được phê duyệt theo Kế hoạch quản lý rủi ro.
...
