Workbook

Sheet DuToan
A1: BẢNG DỰ TOÁN KINH PHÍ
A2: ĐỀ TÀI | B2: Xây dựng hệ thống quản lý hàng hóa và kho bãi sản phẩm thời trang
A3: MÃ SỐ | B3: CNTT20261_N01
A4: CHỦ TRÌ | B4: Bùi Tuấn Anh
A5: THỜI GIAN | B5: 01/09/2026 ~ 31/03/2027
A7: TT | B7: Danh mục | C7: Số tiền (VNĐ) | D7: Ghi chú
A8: 1 | B8: Công lao động | C8: =CongLaoDong!G13 -> 285396650 | D8: Chi tiết tại sheet CongLaoDong, ChuyenDe
A9: 2 | B9: Vật tư, Thiết bị | C9: =ThietBiVatTu!F29 -> 73800000 | D9: Chi tiết tại sheet ThietBiVatTu
A10: 3 | B10: Chi khác (VPP, Công tác, Quản lý...) | C10: =ChiKhac!D27 -> 49000000 | D10: Chi tiết tại sheet ChiKhac
A11: Tổng | C11: =SUM(C8:C10) -> 408196650
A13: Bằng chữ: Bốn trăm linh tám triệu một trăm chín mươi sáu nghìn sáu trăm năm mươi đồng
C15: Hà Nội, Ngày 25 tháng 7 năm 2026
A16: Chủ nhiệm đề tài | C16: Người lập bảng
A20: Bùi Tuấn Anh | C20: Bùi Tuấn Anh

Sheet CongLaoDong
A1: PHỤ LỤC DỰ TOÁN KINH PHÍ 1. Nhân công lao động khoa học (khoán chi)
A2: ĐỀ TÀI | B2: Xây dựng hệ thống quản lý hàng hóa và kho bãi sản phẩm thời trang
A3: MÃ SỐ | B3: CNTT20261_N01
A4: CHỦ TRÌ | B4: Bùi Tuấn Anh
A5: Công lao động khoa học thực hiện theo mức lương cơ sở: | E5: 2530000
A7: TT | B7: Họ và tên | C7: Nhiệm vụ | D7: Số ngày công | E7: Hệ số nhiệm vụ | F7: Định mức / ngày công | G7: Thành tiền
A8: 1 | B8: Bùi Tuấn Anh | C8: Chủ trì | D8: =SUMIF(ChuyenDe!$G$2:$G$61, $B8, ChuyenDe!$H$2:$H$61) -> 43.266667 | E8: 0.75 | F8: =E8*$E$5 -> 1897500 | G8: =D8*F8 -> 82098500
A9: 2 | B9: Bùi Quốc Luýt | C9: Thành viên chính | D9: =SUMIF(ChuyenDe!$G$2:$G$61, $B9, ChuyenDe!$H$2:$H$61) -> 48.95 | E9: 0.45 | F9: =E9*$E$5 -> 1138500 | G9: =D9*F9 -> 55729575
A10: 3 | B10: Vũ Quang Minh | C10: Thành viên chính | D10: =SUMIF(ChuyenDe!$G$2:$G$61, $B10, ChuyenDe!$H$2:$H$61) -> 41.983333 | E10: 0.45 | F10: =E10*$E$5 -> 1138500 | G10: =D10*F10 -> 47798025
A11: 4 | B11: Bạch Minh Quang | C11: Thành viên chính | D11: =SUMIF(ChuyenDe!$G$2:$G$61, $B11, ChuyenDe!$H$2:$H$61) -> 44 | E11: 0.45 | F11: =E11*$E$5 -> 1138500 | G11: =D11*F11 -> 50094000
A12: 5 | B12: Phạm Đoàn Bảo Thiên | C12: Thành viên chính | D12: =SUMIF(ChuyenDe!$G$2:$G$61, $B12, ChuyenDe!$H$2:$H$61) -> 43.633333 | E12: 0.45 | F12: =E12*$E$5 -> 1138500 | G12: =D12*F12 -> 49676550
A13: Tổng | D13: =SUM(D8:D12) -> 221.83333 | F13: =AVERAGE(F8:F12) -> 1290300 | G13: =SUM(G8:G12) -> 285396650
A15: Bằng chữ: Hai trăm tám mươi lăm triệu ba trăm chín mươi sáu nghìn sáu trăm năm mươi đồng
D17: Hà Nội, Ngày 25 tháng 7 năm 2026
B18: Chủ nhiệm đề tài | D18: Người lập bảng
B22: Bùi Tuấn Anh | D22: Bùi Tuấn Anh

Sheet ChuyenDe
A1: STT | B1: Các nội dung, công việc thực hiện | C1: Sản phẩm | D1: Thời gian | E1: Tiến trình | F1: Nhiệm vụ | G1: Người thực hiện | H1: Công số (manday) | I1: Định mức | J1: Giá trị | K1: Lương cơ sở | L1: =CongLaoDong!E5 -> 2530000
A2: A. KHẢO SÁT & YÊU CẦU
A3: 1 | B3: Khảo sát cách kho nhận hàng từ nhà cung cấp, kiểm tra mẫu mã, màu, size, đối chiếu hóa đơn nhập; cách tiếp nhận và phân loại hàng khách trả lại. | C3: Báo cáo khảo sát & đặc tả yêu cầu | D3: 01/09/2026-25/09/2026 | E3: Từ đầu | F3: Chủ nhiệm | G3: Bùi Tuấn Anh | H3: 3.4833333 | I3: =VLOOKUP(G3,CongLaoDong!$B$8:$F$12,5,0) -> 1897500 | J3: =H3*I3 -> 6609625
A4: 2 | B4: Khảo sát cách bộ phận bán hàng gửi yêu cầu xuất, cách kho soạn hàng, chuyển hàng giữa kho tổng và kho cửa hàng, xử lý hàng lỗi hỏng. | C4: Báo cáo khảo sát & đặc tả yêu cầu | E4: Từ đầu | F4: Thành viên chính | G4: Bùi Quốc Luýt | H4: 3.4833333 | I4: =VLOOKUP(G4,CongLaoDong!$B$8:$F$12,5,0) -> 1138500 | J4: =H4*I4 -> 3965775
A5: 3 | B5: Khảo sát quy trình kiểm kê, đối chiếu sổ sách; thu thập 13 biểu mẫu gồm 7 phiếu chứng từ và 6 mẫu báo cáo đang sử dụng. | C5: Báo cáo khảo sát & đặc tả yêu cầu | E5: Từ đầu | F5: Thành viên chính | G5: Phạm Đoàn Bảo Thiên | H5: 4.4 | I5: =VLOOKUP(G5,CongLaoDong!$B$8:$F$12,5,0) -> 1138500 | J5: =H5*I5 -> 5009400
A6: 4 | B6: Khảo sát cách ghi nhận sản phẩm, loại, màu, size, giá nhập, giá bán, vị trí lưu trữ; xác định cấp quản lý đúng (sản phẩm hay biến thể). | C6: Báo cáo khảo sát & đặc tả yêu cầu | E6: Từ đầu | F6: Thành viên chính | G6: Bạch Minh Quang | H6: 2.3833333 | I6: =VLOOKUP(G6,CongLaoDong!$B$8:$F$12,5,0) -> 1138500 | J6: =H6*I6 -> 2713425
A7: 5 | B7: Tổng hợp kết quả khảo sát, mô tả 4 quy trình cốt lõi, liệt kê hạn chế của cách quản lý bằng sổ sách và Excel, đối chiếu vấn đề với nhu cầu hệ thống. | C7: Báo cáo khảo sát & đặc tả yêu cầu | E7: Sau Task 1, 2, 3, 4 | F7: Chủ nhiệm | G7: Bùi Tuấn Anh | H7: 3.3 | I7: =VLOOKUP(G7,CongLaoDong!$B$8:$F$12,5,0) -> 1897500 | J7: =H7*I7 -> 6261750
A8: 6 | B8: Xác định mục tiêu đo được, phạm vi trong và ngoài hệ thống, tác nhân và các quy tắc nghiệp vụ QT-01 đến QT-06 (tồn không âm, chỉ đổi tồn khi phiếu hoàn thành...). | C8: Báo cáo khảo sát & đặc tả yêu cầu | E8: Sau Task 5 | F8: Chủ nhiệm | G8: Bùi Tuấn Anh | H8: 3.3 | I8: =VLOOKUP(G8,CongLaoDong!$B$8:$F$12,5,0) -> 1897500 | J8: =H8*I8 -> 6261750
A9: 7 | B9: Lập danh sách 19 yêu cầu chức năng (FR) và 11 yêu cầu phi chức năng (NFR) kèm tiêu chí đo về hiệu năng, toàn vẹn dữ liệu, bảo mật. | C9: Báo cáo khảo sát & đặc tả yêu cầu | E9: Sau Task 6 | F9: Thành viên chính | G9: Bùi Quốc Luýt | H9: 4.5833333 | I9: =VLOOKUP(G9,CongLaoDong!$B$8:$F$12,5,0) -> 1138500 | J9: =H9*I9 -> 5218125
A10: 8 | B10: Trao đổi với quản lý kho và bộ phận bán hàng của doanh nghiệp, tiếp nhận phản hồi và chốt tài liệu đặc tả yêu cầu. | C10: Báo cáo khảo sát & đặc tả yêu cầu | E10: Sau Task 7 | F10: Chủ nhiệm | G10: Bùi Tuấn Anh | H10: 2.2 | I10: =VLOOKUP(G10,CongLaoDong!$B$8:$F$12,5,0) -> 1897500 | J10: =H10*I10 -> 4174500
A11: B. PHÂN TÍCH & THIẾT KẾ HỆ THỐNG
A12: 9 | B12: Xác định tác nhân Người dùng, Quản lý, Nhân viên kho, Nhân viên bán hàng; lập ma trận phân quyền vai trò - use case làm căn cứ RBAC. | C12: Báo cáo phân tích thiết kế (UML) | D12: 26/09/2026-20/11/2026 | E12: Sau Task 8 | F12: Chủ nhiệm | G12: Bùi Tuấn Anh | H12: 2.2 | I12: =VLOOKUP(G12,CongLaoDong!$B$8:$F$12,5,0) -> 1897500 | J12: =H12*I12 -> 4174500
A13: 10 | B13: Vẽ biểu đồ use case tổng quát và phân rã 4 gói: Quản trị hệ thống, Quản lý danh mục, Nghiệp vụ kho, Tồn kho và báo cáo. | C13: Báo cáo phân tích thiết kế (UML) | E13: Sau Task 9 | F13: Chủ nhiệm | G13: Bùi Tuấn Anh | H13: 3.3 | I13: =VLOOKUP(G13,CongLaoDong!$B$8:$F$12,5,0) -> 1897500 | J13: =H13*I13 -> 6261750
A14: 11 | B14: Đặc tả luồng chính, luồng thay thế, điều kiện trước/sau cho 19 use case, chi tiết nhất cho Nhập kho, Xuất kho, Duyệt điều chỉnh tồn, Đổi trả. | C14: Báo cáo phân tích thiết kế (UML) | E14: Sau Task 10 | F14: Thành viên chính | G14: Phạm Đoàn Bảo Thiên | H14: 6.6 | I14: =VLOOKUP(G14,CongLaoDong!$B$8:$F$12,5,0) -> 1138500 | J14: =H14*I14 -> 7514100
A15: 12 | B15: Xây dựng mô hình lĩnh vực (sản phẩm, biến thể, kho, tồn kho, phiếu kho, thẻ kho) và biểu đồ lớp phân tích theo mẫu BCE cho các use case trọng tâm. | C15: Báo cáo phân tích thiết kế (UML) | E15: Sau Task 11 | F15: Chủ nhiệm | G15: Bùi Tuấn Anh | H15: 5.5 | I15: =VLOOKUP(G15,CongLaoDong!$B$8:$F$12,5,0) -> 1897500 | J15: =H15*I15 -> 10436250
A16: 13 | B16: Vẽ 4 biểu đồ tuần tự cho UC Nhập kho, Xuất kho, Duyệt điều chỉnh tồn kho, Xử lý đổi trả hàng. | C16: Báo cáo phân tích thiết kế (UML) | E16: Sau Task 12 | F16: Thành viên chính | G16: Vũ Quang Minh | H16: 5.5 | I16: =VLOOKUP(G16,CongLaoDong!$B$8:$F$12,5,0) -> 1138500 | J16: =H16*I16 -> 6261750
A17: 14 | B17: Vẽ 4 biểu đồ hoạt động (nghiệp vụ tổng quát, yêu cầu và xuất kho, kiểm kê, đổi trả) và 2 biểu đồ trạng thái của PhieuKho, PhieuKiemKe. | C17: Báo cáo phân tích thiết kế (UML) | E17: Sau Task 11 | F17: Thành viên chính | G17: Bạch Minh Quang | H17: 4.5833333 | I17: =VLOOKUP(G17,CongLaoDong!$B$8:$F$12,5,0) -> 1138500 | J17: =H17*I17 -> 5218125
A18: 15 | B18: Chọn kiến trúc web 3 tầng (React - Spring Boot - PostgreSQL), chia 6 hệ thống con, tổ chức biểu đồ gói theo BCE và quy tắc phụ thuộc. | C18: Báo cáo phân tích thiết kế (UML) | E18: Sau Task 12 | F18: Thành viên chính | G18: Bùi Quốc Luýt | H18: 4.5833333 | I18: =VLOOKUP(G18,CongLaoDong!$B$8:$F$12,5,0) -> 1138500 | J18: =H18*I18 -> 5218125
A19: 16 | B19: Mô tả các thành phần phần mềm, REST API cung cấp; bố trí máy chủ ứng dụng, máy chủ CSDL, lưu trữ sao lưu và máy tính bảng tại kho. | C19: Báo cáo phân tích thiết kế (UML) | E19: Sau Task 15 | F19: Thành viên chính | G19: Vũ Quang Minh | H19: 3.3 | I19: =VLOOKUP(G19,CongLaoDong!$B$8:$F$12,5,0) -> 1138500 | J19: =H19*I19 -> 3757050
A20: 17 | B20: Chi tiết hóa lớp thiết kế: kiểu dữ liệu, tầm vực, phương thức cho nhóm chứng từ kho, tồn kho và kiểm kê, danh mục hàng hóa và quản trị. | C20: Báo cáo phân tích thiết kế (UML) | E20: Sau Task 13, 15 | F20: Thành viên chính | G20: Bùi Quốc Luýt | H20: 5.5 | I20: =VLOOKUP(G20,CongLaoDong!$B$8:$F$12,5,0) -> 1138500 | J20: =H20*I20 -> 6261750
A21: C. THIẾT KẾ CƠ SỞ DỮ LIỆU & GIAO DIỆN
A22: 18 | B22: Ánh xạ lớp thực thể sang 15 bảng, xác định khóa chính, khóa ngoại, quan hệ giữa sản phẩm, biến thể, kho, tồn kho, phiếu kho và thẻ kho. | C22: Lược đồ CSDL & từ điển dữ liệu | D22: 21/11/2026-25/12/2026 | E22: Sau Task 17 | F22: Thành viên chính | G22: Phạm Đoàn Bảo Thiên | H22: 4.5833333 | I22: =VLOOKUP(G22,CongLaoDong!$B$8:$F$12,5,0) -> 1138500 | J22: =H22*I22 -> 5218125
A23: 19 | B23: Đặc tả chi tiết từng cột; ràng buộc CHECK tồn không âm, UNIQUE (kho, biến thể), chỉ mục thẻ kho theo (biến thể, kho, thời gian). | C23: Lược đồ CSDL & từ điển dữ liệu | E23: Sau Task 18 | F23: Thành viên chính | G23: Phạm Đoàn Bảo Thiên | H23: 4.2166667 | I23: =VLOOKUP(G23,CongLaoDong!$B$8:$F$12,5,0) -> 1138500 | J23: =H23*I23 -> 4800675
A24: 20 | B24: Viết script migration tạo bảng, khóa, ràng buộc trên PostgreSQL 16 và bộ dữ liệu mẫu (sản phẩm nhiều màu/size, nhiều kho) phục vụ phát triển. | C24: Lược đồ CSDL & từ điển dữ liệu | E24: Sau Task 19 | F24: Thành viên chính | G24: Vũ Quang Minh | H24: 3.4833333 | I24: =VLOOKUP(G24,CongLaoDong!$B$8:$F$12,5,0) -> 1138500 | J24: =H24*I24 -> 3965775
A25: 21 | B25: Thiết kế luồng chuyển 10 màn hình, bố cục menu trái hiển thị theo quyền, ô tìm SKU nhận dữ liệu từ máy quét mã vạch, responsive cho máy tính bảng 10 inch. | C25: Thiết kế UI/UX hệ thống | E25: Sau Task 17 | F25: Thành viên chính | G25: Bạch Minh Quang | H25: 3.3 | I25: =VLOOKUP(G25,CongLaoDong!$B$8:$F$12,5,0) -> 1138500 | J25: =H25*I25 -> 3757050
A26: 22 | B26: Thiết kế MH-01 Đăng nhập và MH-02 Tổng quan hiển thị cảnh báo hết hàng, sắp hết và các phiếu chờ xử lý. | C26: Thiết kế UI/UX hệ thống | E26: Sau Task 21 | F26: Thành viên chính | G26: Bạch Minh Quang | H26: 2.2 | I26: =VLOOKUP(G26,CongLaoDong!$B$8:$F$12,5,0) -> 1138500 | J26: =H26*I26 -> 2504700
A27: 23 | B27: Thiết kế MH-03 quản lý mẫu sản phẩm, sinh ma trận màu x size, khai báo giá nhập, giá bán, tồn tối thiểu cho từng biến thể. | C27: Thiết kế UI/UX hệ thống | E27: Sau Task 21 | F27: Thành viên chính | G27: Bạch Minh Quang | H27: 3.3 | I27: =VLOOKUP(G27,CongLaoDong!$B$8:$F$12,5,0) -> 1138500 | J27: =H27*I27 -> 3757050
A28: 24 | B28: Thiết kế MH-04 Lập phiếu nhập kho, MH-05 Xử lý phiếu xuất, MH-08 Đổi trả hàng với thao tác quét hàng, hiển thị tồn khả dụng và thông báo lỗi. | C28: Thiết kế UI/UX hệ thống | E28: Sau Task 21 | F28: Thành viên chính | G28: Bạch Minh Quang | H28: 4.5833333 | I28: =VLOOKUP(G28,CongLaoDong!$B$8:$F$12,5,0) -> 1138500 | J28: =H28*I28 -> 5218125
A29: 25 | B29: Thiết kế MH-06 Kiểm kê, MH-07 Duyệt kiểm kê, MH-09 Tra cứu tồn kho và thẻ kho, MH-10 Báo cáo với bộ lọc và xuất Excel. | C29: Thiết kế UI/UX hệ thống | E29: Sau Task 21 | F29: Chủ nhiệm | G29: Bùi Tuấn Anh | H29: 4.2166667 | I29: =VLOOKUP(G29,CongLaoDong!$B$8:$F$12,5,0) -> 1897500 | J29: =H29*I29 -> 8001125
A30: D. XÂY DỰNG CHƯƠNG TRÌNH
A31: 26 | B31: Khởi tạo dự án Spring Boot 3 và ReactJS/TypeScript, cấu hình Docker, kho mã nguồn, quy ước code và pipeline build tự động. | C31: Mã nguồn & module chạy được | D31: 26/12/2026-15/02/2027 | E31: Sau Task 20 | F31: Thành viên chính | G31: Bùi Quốc Luýt | H31: 3.3 | I31: =VLOOKUP(G31,CongLaoDong!$B$8:$F$12,5,0) -> 1138500 | J31: =H31*I31 -> 3757050
A32: 27 | B32: Xây dựng đăng nhập JWT, đổi mật khẩu, khóa tài khoản sau 5 lần sai; quản lý tài khoản, gán vai trò và kho phụ trách (UC-1.1, UC-1.2). | C32: Mã nguồn & module chạy được | E32: Sau Task 26 | F32: Thành viên chính | G32: Bùi Quốc Luýt | H32: 4.5833333 | I32: =VLOOKUP(G32,CongLaoDong!$B$8:$F$12,5,0) -> 1138500 | J32: =H32*I32 -> 5218125
A33: 28 | B33: Xây dựng CRUD loại sản phẩm, màu sắc, kích thước, nhà cung cấp, kho và vị trí kho (UC-2.3, UC-2.4, UC-2.5). | C33: Mã nguồn & module chạy được | E33: Sau Task 26 | F33: Thành viên chính | G33: Vũ Quang Minh | H33: 4.5833333 | I33: =VLOOKUP(G33,CongLaoDong!$B$8:$F$12,5,0) -> 1138500 | J33: =H33*I33 -> 5218125
A34: 29 | B34: Xây dựng quản lý sản phẩm, sinh biến thể theo màu x size, tự sinh mã SKU, tìm kiếm và lọc theo loại, trạng thái (UC-2.1, UC-2.2). | C34: Mã nguồn & module chạy được | E34: Sau Task 28 | F34: Thành viên chính | G34: Vũ Quang Minh | H34: 5.5 | I34: =VLOOKUP(G34,CongLaoDong!$B$8:$F$12,5,0) -> 1138500 | J34: =H34*I34 -> 6261750
A35: 30 | B35: Xây dựng dịch vụ tăng, trừ, điều chỉnh tồn có khóa dòng (SELECT ... FOR UPDATE), ghi thẻ kho chỉ thêm không sửa, dùng chung cho mọi nghiệp vụ. | C35: Mã nguồn & module chạy được | E35: Sau Task 29 | F35: Thành viên chính | G35: Bùi Quốc Luýt | H35: 5.8666667 | I35: =VLOOKUP(G35,CongLaoDong!$B$8:$F$12,5,0) -> 1138500 | J35: =H35*I35 -> 6679200
A36: 31 | B36: Xây dựng lập phiếu nhập theo nhà cung cấp, quét SKU, hoàn tất phiếu trong một giao dịch: cộng tồn, ghi thẻ kho, đổi trạng thái (UC-3.1). | C36: Mã nguồn & module chạy được | E36: Sau Task 30 | F36: Thành viên chính | G36: Vũ Quang Minh | H36: 4.5833333 | I36: =VLOOKUP(G36,CongLaoDong!$B$8:$F$12,5,0) -> 1138500 | J36: =H36*I36 -> 5218125
A37: 32 | B37: Xây dựng tạo yêu cầu xuất kèm mã đơn hàng cho nhân viên bán hàng; xử lý xuất kho kiểm tra đủ tồn, không cho tồn âm (UC-3.2, UC-3.3). | C37: Mã nguồn & module chạy được | E37: Sau Task 30 | F37: Thành viên chính | G37: Bùi Quốc Luýt | H37: 5.6833333 | I37: =VLOOKUP(G37,CongLaoDong!$B$8:$F$12,5,0) -> 1138500 | J37: =H37*I37 -> 6470475
A38: 33 | B38: Xây dựng chuyển hàng giữa các kho qua hai bước xuất đi và xác nhận nhận hàng tại kho đích (UC-3.4). | C38: Mã nguồn & module chạy được | E38: Sau Task 32 | F38: Thành viên chính | G38: Vũ Quang Minh | H38: 3.4833333 | I38: =VLOOKUP(G38,CongLaoDong!$B$8:$F$12,5,0) -> 1138500 | J38: =H38*I38 -> 3965775
A39: 34 | B39: Xây dựng phiếu kiểm kê theo phạm vi, tự tính chênh lệch = thực tế - hệ thống; Quản lý duyệt, hệ thống sinh phiếu điều chỉnh (UC-3.5, UC-3.6). | C39: Mã nguồn & module chạy được | E39: Sau Task 30 | F39: Thành viên chính | G39: Phạm Đoàn Bảo Thiên | H39: 5.6833333 | I39: =VLOOKUP(G39,CongLaoDong!$B$8:$F$12,5,0) -> 1138500 | J39: =H39*I39 -> 6470475
A40: 35 | B40: Xây dựng tiếp nhận đổi trả: nhập lại hàng tốt vào kho bán, tách hàng lỗi sang kho hàng lỗi, xuất hàng đổi sang, tính tiền chênh lệch (UC-3.7). | C40: Mã nguồn & module chạy được | E40: Sau Task 32 | F40: Thành viên chính | G40: Phạm Đoàn Bảo Thiên | H40: 4.5833333 | I40: =VLOOKUP(G40,CongLaoDong!$B$8:$F$12,5,0) -> 1138500 | J40: =H40*I40 -> 5218125
...

Sheet ThietBiVatTu
A1: PHỤ LỤC DỰ TOÁN KINH PHÍ 2. Thiết bị vật tư
A2: ĐỀ TÀI | B2: Xây dựng hệ thống quản lý hàng hóa và kho bãi sản phẩm thời trang
A3: MÃ SỐ | B3: CNTT20261_N01
A4: CHỦ TRÌ | B4: Bùi Tuấn Anh
A5: Thiết bị vật tư phục vụ đề tài
A7: STT | B7: TÊN | C7: ĐƠN VỊ TÍNH | D7: SỐ LƯỢNG | E7: ĐƠN GIÁ (VNĐ) | F7: THÀNH TIỀN (VNĐ)
A8: I | B8: Giai đoạn A (Khảo sát hiện trạng & Thu thập yêu cầu)
A9: 1 | B9: Thuê laptop cho nhân sự khảo sát tại kho tổng và cửa hàng (1 tháng) | C9: Bộ | D9: 2 | E9: 2000000 | F9: =D9*E9 -> 4000000
A10: II | B10: Giai đoạn B (Phân tích & Thiết kế hệ thống)
A11: 1 | B11: Thuê bộ máy tính làm việc cho nhóm dự án (2 tháng) | C11: Bộ/tháng | D11: 10 | E11: 1500000 | F11: =D11*E11 -> 15000000
A12: III | B12: Giai đoạn C (Thiết kế cơ sở dữ liệu & Giao diện)
A13: 1 | B13: Thuê bộ máy tính làm việc cho nhóm dự án (1 tháng) | C13: Bộ/tháng | D13: 5 | E13: 1500000 | F13: =D13*E13 -> 7500000
A14: 2 | B14: Tài khoản Figma Professional thiết kế giao diện (2 người x 2 tháng) | C14: Tài khoản/tháng | D14: 4 | E14: 400000 | F14: =D14*E14 -> 1600000
A15: IV | B15: Giai đoạn D (Xây dựng chương trình)
A16: 1 | B16: Thuê bộ máy tính làm việc cho nhóm dự án (2 tháng) | C16: Bộ/tháng | D16: 10 | E16: 1500000 | F16: =D16*E16 -> 15000000
A17: 2 | B17: Cloud Server môi trường Dev/Staging (Docker, PostgreSQL) | C17: Tháng | D17: 2 | E17: 1800000 | F17: =D17*E17 -> 3600000
A18: 3 | B18: Máy quét mã vạch USB phục vụ lập trình, thử nghiệm nhập SKU | C18: Cái | D18: 2 | E18: 1200000 | F18: =D18*E18 -> 2400000
A19: V | B19: Giai đoạn E (Tích hợp & Kiểm thử)
A20: 1 | B20: Thuê bộ máy tính làm việc cho nhóm dự án (1 tháng) | C20: Bộ/tháng | D20: 5 | E20: 1500000 | F20: =D20*E20 -> 7500000
A21: 2 | B21: Cloud Server môi trường Testing, kiểm thử hiệu năng 50.000 biến thể | C21: Tháng | D21: 1 | E21: 2500000 | F21: =D21*E21 -> 2500000
A22: 3 | B22: Thuê máy tính bảng 10 inch kiểm thử giao diện tại kho (1 tháng) | C22: Cái | D22: 2 | E22: 800000 | F22: =D22*E22 -> 1600000
A23: VI | B23: Giai đoạn F (Triển khai & Bàn giao)
A24: 1 | B24: Thuê bộ máy tính làm việc cho nhóm dự án (nửa tháng) | C24: Bộ | D24: 5 | E24: 750000 | F24: =D24*E24 -> 3750000
A25: 2 | B25: Máy chủ ứng dụng Production 4 vCPU, 8 GB RAM (tháng đầu vận hành) | C25: Tháng | D25: 1 | E25: 3500000 | F25: =D25*E25 -> 3500000
A26: 3 | B26: Máy chủ CSDL Production 4 vCPU, 16 GB RAM, SSD 200 GB (tháng đầu vận hành) | C26: Tháng | D26: 1 | E26: 4500000 | F26: =D26*E26 -> 4500000
A27: 4 | B27: Object Storage lưu bản sao lưu CSDL 30 ngày | C27: Tháng | D27: 1 | E27: 500000 | F27: =D27*E27 -> 500000
A28: 5 | B28: Đăng ký tên miền hệ thống (.vn) | C28: Năm | D28: 1 | E28: 850000 | F28: =D28*E28 -> 850000
A29: TỔNG CỘNG | F29: =F9+F11+F13+F14+F16+F17+F18+F20+F21+F22+F24+F25+F26+F27+F28 -> 73800000
A31: Bằng chữ: Bảy mươi ba triệu tám trăm nghìn đồng
D33: Hà Nội, Ngày 25 tháng 7 năm 2026
B34: Chủ nhiệm đề tài | D34: Người lập bảng
B38: Bùi Tuấn Anh | D38: Bùi Tuấn Anh

Sheet ChiKhac
A1: PHỤ LỤC DỰ TOÁN KINH PHÍ 3. Chi khác
A2: ĐỀ TÀI | B2: Xây dựng hệ thống quản lý hàng hóa và kho bãi sản phẩm thời trang
A3: MÃ SỐ | B3: CNTT20261_N01
A4: CHỦ TRÌ | B4: Bùi Tuấn Anh
A5: Chi khác phục vụ đề tài
A7: STT | B7: NỘI DUNG | C7: Mô tả chi tiết | D7: SỐ TIỀN (VNĐ)
A8: Giai đoạn A (Khảo sát hiện trạng & thu thập yêu cầu - Tháng 09/2026)
A9: 1 | B9: Văn phòng phẩm (phô tô, in ấn tài liệu) | C9: In phiếu phỏng vấn, bảng hỏi khảo sát; photo 13 biểu mẫu phiếu kho và báo cáo đang sử dụng; in Tôn chỉ dự án. | D9: 1500000
A10: 2 | B10: Chi phí khảo sát (đi lại, workshop...) | C10: Di chuyển đến kho tổng và các kho cửa hàng để quan sát quy trình nhập, xuất, kiểm kê, đổi trả; phỏng vấn quản lý kho, nhân viên kho, nhân viên bán hàng. | D10: 4000000
A11: Giai đoạn B (Phân tích & thiết kế hệ thống - Tháng 09/2026 - 11/2026)
A12: 1 | B12: Văn phòng phẩm (phô tô, in ấn tài liệu) | C12: In tài liệu đặc tả yêu cầu (19 FR, 11 NFR), biểu đồ use case và đặc tả 19 use case để rà soát với doanh nghiệp. | D12: 1500000
A13: 2 | B13: Chi phí khảo sát (đi lại, workshop...) | C13: Tổ chức 01 buổi workshop thống nhất quy tắc nghiệp vụ QT-01 đến QT-06 và ma trận phân quyền với Ban Giám đốc và quản lý kho. | D13: 3000000
A14: Giai đoạn C (Thiết kế cơ sở dữ liệu & giao diện - Tháng 11/2026 - 12/2026)
A15: 1 | B15: Chi phí khảo sát (đi lại, workshop...) | C15: Tổ chức buổi duyệt prototype 10 màn hình với nhân viên kho, thử thao tác quét mã vạch trên bản mẫu. | D15: 3000000
A16: 2 | B16: Chi phí phục vụ OT (tiền nước, ăn uống ... cho nhân sự) | C16: Hỗ trợ ăn uống cho nhân sự tăng ca hoàn thiện lược đồ 15 bảng, từ điển dữ liệu và ràng buộc toàn vẹn. | D16: 5000000
A17: Giai đoạn D (Xây dựng chương trình - Tháng 12/2026 - 02/2027)
A18: 1 | B18: Văn phòng phẩm (in tem mã vạch) | C18: In tem mã vạch SKU mẫu trên giấy decal để thử nghiệm quét khi lập phiếu nhập, xuất, kiểm kê. | D18: 1000000
A19: 2 | B19: Chi phí phục vụ OT (tiền nước, ăn uống ... cho nhân sự) | C19: Bồi dưỡng lập trình viên tăng ca hoàn thiện dịch vụ tồn kho, thẻ kho và các nghiệp vụ nhập, xuất, chuyển kho, kiểm kê, đổi trả. | D19: 10000000
A20: Giai đoạn E (Tích hợp & kiểm thử - Tháng 02/2027 - 03/2027)
A21: 1 | B21: Chi phí khảo sát (đi lại, workshop...) | C21: Chi phí đi lại, nước uống tổ chức kiểm thử chấp nhận người dùng (UAT) tại kho tổng và cửa hàng. | D21: 3000000
A22: 2 | B22: Chi phí phục vụ OT (tiền nước, ăn uống ... cho nhân sự) | C22: Hỗ trợ nhân sự tăng ca sửa lỗi phát sinh sau kiểm thử tích hợp, kiểm thử đồng thời và hiệu năng. | D22: 8000000
A23: Giai đoạn F (Triển khai & bàn giao - Tháng 03/2027)
A24: 1 | B24: Văn phòng phẩm (phô tô, in ấn tài liệu) | C24: In tài liệu hướng dẫn sử dụng theo 3 vai trò, tài liệu vận hành và hồ sơ nghiệm thu. | D24: 2000000
A25: 2 | B25: Chi phí đào tạo người dùng | C25: Thuê phòng, nước uống, đi lại tổ chức các buổi đào tạo cho quản lý, nhân viên kho và nhân viên bán hàng. | D25: 4000000
A26: 3 | B26: Chi phí phục vụ OT (tiền nước, ăn uống ... cho nhân sự) | C26: Hỗ trợ nhân sự tăng ca chuyển đổi dữ liệu tồn đầu kỳ từ các file Excel và triển khai hệ thống. | D26: 3000000
A27: TỔNG CỘNG | D27: =SUM(D8:D26) -> 49000000
A29: Bằng chữ: Bốn mươi chín triệu đồng
C31: Hà Nội, Ngày 25 tháng 7 năm 2026
B32: Chủ nhiệm đề tài | C32: Người lập bảng
B36: Bùi Tuấn Anh | C36: Bùi Tuấn Anh
