Workbook

Sheet DuToan
A1: BẢNG DỰ TOÁN KINH PHÍ
A2: ĐỀ TÀI | B2: Xây dựng hệ thống quản lý du học sinh bậc đại học của trung tâm tư vấn vấn du học Amec
A3: MÃ SỐ | B3: CNTT20261_N03
A4: CHỦ TRÌ | B4: Bùi Thanh Phương
A5: THỜI GIAN | B5: 01/09/2026 ~ 31/03/2027
A7: TT | B7: Danh mục | C7: Số tiền | D7: Ghi chú
A8: 1 | B8: Công lao động | C8: =CongLaoDong!G13 -> 342865600
A9: 2 | B9: Vật tư, Thiết bị | C9: =ThietBiVatTu!F25 -> 80325000
A10: 3 | B10: Chi Khác (VPP, Công tác, Quản lý..) | C10: =ChiKhac!D26 -> 51900000
B11: Tổng | C11: =SUM(C8:C10) -> 475090600
A12: Bằng chữ: Bốn trăm bảy mươi lăm triệu không trăm chín mươi nghìn sáu trăm đồng
B15: Hà Nội, Ngày 13 tháng 9 năm 2026
B16: Chủ nhiệm đề tài

Sheet ChuyenDe
A1: STT | B1: Các nội dung, công việc thực hiện | C1: Sản phẩm | D1: Thời gian | E1: Tiến trình | F1: Nhiệm vụ | G1: Người thực hiện | H1: Công số (manday) | I1: Định mức | J1: Gía trị | K1: Lương tối thiểu | L1: 2530000
A2: A. KHẢO SÁT & YÊU CẦU
A3: 1 | B3: Khảo sát cách trung tâm tiếp nhận nhu cầu, tư vấn quốc gia, trường, ngành học và theo dõi quá trình tư vấn cho du học sinh. | C3: Báo cáo nghiên cứu | D3: 01/09/2026-25/09/2026 | E3: Từ đầu | F3: Chủ nhiệm | G3: Bùi Thanh Phương | H3: 4.5833333 | I3: =VLOOKUP(G3,CongLaoDong!$B$8:$F$12,5,0) -> 1897500 | J3: =H3*I3 -> 8696875
A4: 2 | B4: Khảo sát quy trình tiếp nhận, kiểm tra, cập nhật và lưu trữ thông tin hồ sơ của du học sinh. | C4: Báo cáo nghiên cứu | E4: Từ đầu | F4: Chủ nhiệm | G4: Bùi Thanh Phương | H4: 4.5833333 | I4: =VLOOKUP(G4,CongLaoDong!$B$8:$F$12,5,0) -> 1897500 | J4: =H4*I4 -> 8696875
A5: 3 | B5: Khảo sát quy trình quản lý hồ sơ Visa, tình trạng Visa, thời hạn Visa và quá trình gia hạn Visa cho du học sinh. | C5: Báo cáo nghiên cứu | E5: Từ đầu | F5: Chủ nhiệm | G5: Bùi Thanh Phương | H5: 4.4 | I5: =VLOOKUP(G5,CongLaoDong!$B$8:$F$12,5,0) -> 1897500 | J5: =H5*I5 -> 8349000
A6: 4 | B6: Khảo sát cách trung tâm quản lý học phí, hóa đơn, các khoản thanh toán và tình trạng tài chính của du học sinh. | C6: Báo cáo nghiên cứu | E6: Từ đầu | F6: Chủ nhiệm | G6: Bùi Thanh Phương | H6: 3.4833333 | I6: =VLOOKUP(G6,CongLaoDong!$B$8:$F$12,5,0) -> 1897500 | J6: =H6*I6 -> 6609625
A7: 5 | B7: Tổng hợp kết quả khảo sát, xác định quy trình hiện tại, các vấn đề còn tồn tại và nhu cầu cần giải quyết bằng hệ thống. | C7: Báo cáo nghiên cứu | E7: Sau Task 4 | F7: Chủ nhiệm | G7: Bùi Thanh Phương | H7: 4.5833333 | I7: =VLOOKUP(G7,CongLaoDong!$B$8:$F$12,5,0) -> 1897500 | J7: =H7*I7 -> 8696875
A8: 6 | B8: Phân tích các yêu cầu chức năng và phi chức năng dựa trên quy trình hoạt động và nhu cầu sử dụng của trung tâm. | C8: Báo cáo nghiên cứu | E8: Sau Task 5 | F8: Thành viên chính | G8: Trần Thanh Ngân | H8: 5.6833333 | I8: =VLOOKUP(G8,CongLaoDong!$B$8:$F$12,5,0) -> 1138500 | J8: =H8*I8 -> 6470475
A9: 7 | B9: Chuyển các yêu cầu đã phân tích thành tài liệu đặc tả làm cơ sở cho việc phân tích, thiết kế và xây dựng hệ thống. | C9: Báo cáo nghiên cứu | E9: Sau Task 5 | F9: Thành viên chính | G9: Trần Thanh Ngân | H9: 5.5 | I9: =VLOOKUP(G9,CongLaoDong!$B$8:$F$12,5,0) -> 1138500 | J9: =H9*I9 -> 6261750
A10: 8 | B10: Trao đổi với người dùng, tiếp nhận ý kiến phản hồi và điều chỉnh các yêu cầu để bảo đảm phù hợp với nghiệp vụ. | C10: Báo cáo nghiên cứu | E10: Sau Task 7 | F10: Thành viên chính | G10: Trần Thanh Ngân | H10: 3.4833333 | I10: =VLOOKUP(G10,CongLaoDong!$B$8:$F$12,5,0) -> 1138500 | J10: =H10*I10 -> 3965775
A11: B. PHÂN TÍCH & THIẾT KẾ HỆ THỐNG
A12: 9 | B12: Xác định các tác nhân tham gia hệ thống như quản trị viên, nhân viên tư vấn và du học sinh. | C12: Biểu đồ Lớp chi tiết, Mô hình ERD & Đặc tả các bảng CSDL | D12: 25/09/2026-24/11/2026 | E12: Sau Task 8 | F12: Chủ nhiệm | G12: Bùi Thanh Phương | H12: 3.3 | I12: =VLOOKUP(G12,CongLaoDong!$B$8:$F$12,5,0) -> 1897500 | J12: =H12*I12 -> 6261750
A13: 10 | B13: Xác định các chức năng mà từng Actor được phép thực hiện trên hệ thống quản lý du học sinh. | C13: Biểu đồ Lớp chi tiết, Mô hình ERD & Đặc tả các bảng CSDL | E13: Sau Task 8 | F13: Chủ nhiệm | G13: Bùi Thanh Phương | H13: 4.5833333 | I13: =VLOOKUP(G13,CongLaoDong!$B$8:$F$12,5,0) -> 1897500 | J13: =H13*I13 -> 8696875
A14: 11 | B14: Xây dựng biểu đồ Use Case tổng quát thể hiện Actor, các chức năng và mối quan hệ giữa các chức năng của hệ thống. | C14: Biểu đồ Lớp chi tiết, Mô hình ERD & Đặc tả các bảng CSDL | E14: Sau Task 8 | F14: Chủ nhiệm | G14: Bùi Thanh Phương | H14: 3.4833333 | I14: =VLOOKUP(G14,CongLaoDong!$B$8:$F$12,5,0) -> 1897500 | J14: =H14*I14 -> 6609625
A15: 12 | B15: Mô tả chi tiết luồng chính, luồng thay thế, điều kiện trước/sau và xử lý của từng Use Case. | C15: Biểu đồ Lớp chi tiết, Mô hình ERD & Đặc tả các bảng CSDL | E15: Sau Task 11 | F15: Chủ nhiệm | G15: Bùi Thanh Phương | H15: 6.6 | I15: =VLOOKUP(G15,CongLaoDong!$B$8:$F$12,5,0) -> 1897500 | J15: =H15*I15 -> 12523500
A16: 13 | B16: Xây dựng mô hình lớp gồm các lớp dữ liệu, thuộc tính, phương thức và mối quan hệ phục vụ hệ thống. | C16: Biểu đồ Lớp chi tiết, Mô hình ERD & Đặc tả các bảng CSDL | E16: Sau Task 12 | F16: Thành viên chính | G16: Trần Thanh Ngân | H16: 6.7833333 | I16: =VLOOKUP(G16,CongLaoDong!$B$8:$F$12,5,0) -> 1138500 | J16: =H16*I16 -> 7722825
A17: 14 | B17: Mô hình hóa trình tự tương tác giữa người dùng, giao diện và các thành phần hệ thống khi thực hiện chức năng. | C17: Biểu đồ Lớp chi tiết, Mô hình ERD & Đặc tả các bảng CSDL | E17: Sau Task 12 | F17: Thành viên chính | G17: Trần Thanh Ngân | H17: 6.7833333 | I17: =VLOOKUP(G17,CongLaoDong!$B$8:$F$12,5,0) -> 1138500 | J17: =H17*I17 -> 7722825
A18: 15 | B18: Mô tả luồng xử lý và các bước hoạt động của những nghiệp vụ chính trong hệ thống. | C18: Biểu đồ Lớp chi tiết, Mô hình ERD & Đặc tả các bảng CSDL | E18: Sau Task 12 | F18: Thành viên chính | G18: Trần Thanh Ngân | H18: 6.7833333 | I18: =VLOOKUP(G18,CongLaoDong!$B$8:$F$12,5,0) -> 1138500 | J18: =H18*I18 -> 7722825
A19: 16 | B19: Xác định kiến trúc tổng thể, các tầng xử lý và cách các thành phần của hệ thống tương tác với nhau. | C19: Biểu đồ Lớp chi tiết, Mô hình ERD & Đặc tả các bảng CSDL | E19: Sau Task 12 | F19: Thành viên chính | G19: Trần Thanh Ngân | H19: 5.5 | I19: =VLOOKUP(G19,CongLaoDong!$B$8:$F$12,5,0) -> 1138500 | J19: =H19*I19 -> 6261750
A20: C. THIẾT KẾ CƠ SỞ DỮ LIỆU & GIAO DIỆN
A21: 17 | B21: Xác định các nhóm dữ liệu cần quản lý như sinh viên, người thân, Visa, trường học, học tập, học bổng và tài chính. | C21: Biểu đồ Lớp chi tiết, Mô hình ERD & Đặc tả các bảng CSDL | D21: 25/11/2026-27/12/2026 | E21: Sau Task 12 | F21: Thành viên chính | G21: Chu Quang Hiếu | H21: 4.5833333 | I21: =VLOOKUP(G21,CongLaoDong!$B$8:$F$12,5,0) -> 1138500 | J21: =H21*I21 -> 5218125
A22: 18 | B22: Xây dựng mô hình thực thể – liên kết, xác định khóa và mối quan hệ giữa các đối tượng dữ liệu trong hệ thống. | C22: Biểu đồ Lớp chi tiết, Mô hình ERD & Đặc tả các bảng CSDL | E22: Sau Task 17 | F22: Thành viên chính | G22: Chu Quang Hiếu | H22: 5.5 | I22: =VLOOKUP(G22,CongLaoDong!$B$8:$F$12,5,0) -> 1138500 | J22: =H22*I22 -> 6261750
A23: 19 | B23: Thiết kế cấu trúc cơ sở dữ liệu phục vụ việc lưu trữ và quản lý thông tin du học sinh và các nghiệp vụ liên quan. | C23: Biểu đồ Lớp chi tiết, Mô hình ERD & Đặc tả các bảng CSDL | E23: Sau Task 18 | F23: Thành viên chính | G23: Chu Quang Hiếu | H23: 6.6 | I23: =VLOOKUP(G23,CongLaoDong!$B$8:$F$12,5,0) -> 1138500 | J23: =H23*I23 -> 7514100
A24: 20 | B24: Xây dựng các bảng dữ liệu, khóa chính, khóa ngoại và các ràng buộc nhằm bảo đảm tính toàn vẹn dữ liệu. | C24: Biểu đồ Lớp chi tiết, Mô hình ERD & Đặc tả các bảng CSDL | E24: Sau Task 19 | F24: Thành viên chính | G24: Chu Quang Hiếu | H24: 5.5 | I24: =VLOOKUP(G24,CongLaoDong!$B$8:$F$12,5,0) -> 1138500 | J24: =H24*I24 -> 6261750
A25: 21 | B25: Thiết kế màn hình đăng nhập, nhập thông tin tài khoản và các thông báo khi đăng nhập không hợp lệ. | C25: Thiết kế UI/UX hệ thống | E25: Sau Task 20 | F25: Thành viên chính | G25: Lê Linh Hương | H25: 3.3 | I25: =VLOOKUP(G25,CongLaoDong!$B$8:$F$12,5,0) -> 1138500 | J25: =H25*I25 -> 3757050
A26: 22 | B26: Thiết kế màn hình thêm, sửa, xóa, xem và tìm kiếm thông tin hồ sơ du học sinh. | C26: Thiết kế UI/UX hệ thống | E26: Sau Task 20 | F26: Thành viên chính | G26: Lê Linh Hương | H26: 5.5 | I26: =VLOOKUP(G26,CongLaoDong!$B$8:$F$12,5,0) -> 1138500 | J26: =H26*I26 -> 6261750
A27: 23 | B27: Thiết kế giao diện quản lý thông tin Visa, thời hạn Visa, học phí, hóa đơn và tình trạng thanh toán. | C27: Thiết kế UI/UX hệ thống | E27: Sau Task 20 | F27: Thành viên chính | G27: Lê Linh Hương | H27: 5.5 | I27: =VLOOKUP(G27,CongLaoDong!$B$8:$F$12,5,0) -> 1138500 | J27: =H27*I27 -> 6261750
A28: 24 | B28: Thiết kế màn hình tổng quan hiển thị các số liệu thống kê về sinh viên, Visa, tài chính và các thông tin cần theo dõi. | C28: Thiết kế UI/UX hệ thống | E28: Sau Task 20 | F28: Thành viên chính | G28: Lê Linh Hương | H28: 4.5833333 | I28: =VLOOKUP(G28,CongLaoDong!$B$8:$F$12,5,0) -> 1138500 | J28: =H28*I28 -> 5218125
A29: D. XÂY DỰNG CHƯƠNG TRÌNH
A30: 25 | B30: Xây dựng chức năng đăng nhập, xác thực tài khoản và phân quyền truy cập theo vai trò người sử dụng. | C30: Prototype UI/UX 1 số màn hình | D30: 25/12/2026-01/03/2027 | E30: Sau Task 20 | F30: Thành viên chính | G30: Nguyễn Đức Hậu | H30: 5.5 | I30: =VLOOKUP(G30,CongLaoDong!$B$8:$F$12,5,0) -> 1138500 | J30: =H30*I30 -> 6261750
A31: 26 | B31: Xây dựng chức năng tạo, cập nhật, khóa/mở khóa và quản lý tài khoản của nhân viên trung tâm. | C31: Prototype UI/UX 1 số màn hình | E31: Sau Task 20 | F31: Thành viên chính | G31: Nguyễn Đức Hậu | H31: 4.5833333 | I31: =VLOOKUP(G31,CongLaoDong!$B$8:$F$12,5,0) -> 1138500 | J31: =H31*I31 -> 5218125
A32: 27 | B32: Xây dựng chức năng thêm, sửa, xóa, xem và quản lý thông tin cá nhân, liên hệ và hồ sơ của du học sinh. | C32: Prototype UI/UX 1 số màn hình | E32: Sau Task 20 | F32: Thành viên chính | G32: Nguyễn Đức Hậu | H32: 6.7833333 | I32: =VLOOKUP(G32,CongLaoDong!$B$8:$F$12,5,0) -> 1138500 | J32: =H32*I32 -> 7722825
A33: 28 | B33: Xây dựng chức năng lưu trữ và cập nhật thông tin người thân, mối quan hệ và thông tin liên hệ của du học sinh. | C33: Prototype UI/UX 1 số màn hình | E33: Sau Task 20 | F33: Thành viên chính | G33: Nguyễn Đức Hậu | H33: 4.5833333 | I33: =VLOOKUP(G33,CongLaoDong!$B$8:$F$12,5,0) -> 1138500 | J33: =H33*I33 -> 5218125
A34: 29 | B34: Xây dựng chức năng quản lý hộ chiếu, loại Visa, ngày cấp, ngày hết hạn, tình trạng và kết quả Visa của du học sinh. | C34: Prototype UI/UX 1 số màn hình | E34: Sau Task 20 | F34: Thành viên chính | G34: Nguyễn Đức Hậu | H34: 6.7833333 | I34: =VLOOKUP(G34,CongLaoDong!$B$8:$F$12,5,0) -> 1138500 | J34: =H34*I34 -> 7722825
A35: 30 | B35: Xây dựng chức năng thêm, sửa, xóa và quản lý thông tin các trường đại học, quốc gia và ngành học liên quan. | C35: Prototype UI/UX 1 số màn hình | E35: Sau Task 20 | F35: Thành viên chính | G35: Nguyễn Đức Hậu | H35: 5.5 | I35: =VLOOKUP(G35,CongLaoDong!$B$8:$F$12,5,0) -> 1138500 | J35: =H35*I35 -> 6261750
A36: 31 | B36: Xây dựng chức năng tìm kiếm và tra cứu thông tin du học sinh theo các tiêu chí phù hợp. | C36: Prototype UI/UX 1 số màn hình | E36: Sau Task 20 | F36: Thành viên chính | G36: Lê Linh Hương | H36: 3.4833333 | I36: =VLOOKUP(G36,CongLaoDong!$B$8:$F$12,5,0) -> 1138500 | J36: =H36*I36 -> 3965775
A37: 32 | B37: Xây dựng chức năng tìm kiếm và tra cứu trường đại học theo quốc gia, trường hoặc các thông tin liên quan. | C37: Prototype UI/UX 1 số màn hình | E37: Sau Task 20 | F37: Thành viên chính | G37: Lê Linh Hương | H37: 3.4833333 | I37: =VLOOKUP(G37,CongLaoDong!$B$8:$F$12,5,0) -> 1138500 | J37: =H37*I37 -> 3965775
A38: 33 | B38: Xây dựng chức năng quản lý thông tin học tập, chương trình học và kết quả học tập của du học sinh. | C38: Prototype UI/UX 1 số màn hình | E38: Sau Task 20 | F38: Thành viên chính | G38: Lê Linh Hương | H38: 5.5 | I38: =VLOOKUP(G38,CongLaoDong!$B$8:$F$12,5,0) -> 1138500 | J38: =H38*I38 -> 6261750
A39: 34 | B39: Xây dựng chức năng cập nhật GPA, tính toán kết quả và hỗ trợ phân loại kết quả học tập của sinh viên. | C39: Prototype UI/UX 1 số màn hình | E39: Sau Task 20 | F39: Thành viên chính | G39: Lê Linh Hương | H39: 4.5833333 | I39: =VLOOKUP(G39,CongLaoDong!$B$8:$F$12,5,0) -> 1138500 | J39: =H39*I39 -> 5218125
A40: 35 | B40: Xây dựng chức năng quản lý thông tin học bổng, điều kiện, kết quả và tình trạng học bổng của du học sinh. | C40: Prototype UI/UX 1 số màn hình | E40: Sau Task 20 | F40: Thành viên chính | G40: Chu Quang Hiếu | H40: 5.5 | I40: =VLOOKUP(G40,CongLaoDong!$B$8:$F$12,5,0) -> 1138500 | J40: =H40*I40 -> 6261750
...

Sheet CongLaoDong
A1: PHỤ LỤC DỰ TOÁN KINH PHÍ 1. Nhân công lao động khoa học (khoán chi)
A2: ĐỀ TÀI | B2: Xây dựng hệ thống quản lý du học sinh bậc đại học của trung tâm tư vấn vấn du học Amec
A3: MÃ SỐ | B3: CNTT20261_N03
A4: CHỦ TRÌ | B4: Bùi Thanh Phương
A5: Công lao động khoa học thực hiện theo mức lương cơ bản: | E5: 2530000
A7: TT | B7: Họ và tên | C7: Nhiệm vụ | D7: Số ngày công | E7: Hệ số nhiệm vụ | F7: Định mức / ngày công | G7: Thành tiền
A8: 1 | B8: Bùi Thanh Phương | C8: Chủ trì | D8: =SUMIF(ChuyenDe!$G$3:$G$59, $B8, ChuyenDe!$H$3:$H$59) -> 55.183333 | E8: 0.75 | F8: =E8*$E$5 -> 1897500 | G8: =D8*F8 -> 104710375
A9: 2 | B9: Nguyễn Đức Hậu | C9: Thành viên chính | D9: =SUMIF(ChuyenDe!$G$3:$G$59, $B9, ChuyenDe!$H$3:$H$59) -> 53.9 | E9: 0.45 | F9: =E9*$E$5 -> 1138500 | G9: =D9*F9 -> 61365150
A10: 3 | B10: Lê Linh Hương | C10: Thành viên chính | D10: =SUMIF(ChuyenDe!$G$3:$G$59, $B10, ChuyenDe!$H$3:$H$59) -> 52.8 | E10: 0.45 | F10: =E10*$E$5 -> 1138500 | G10: =D10*F10 -> 60112800
A11: 4 | B11: Chu Quang Hiếu | C11: Thành viên chính | D11: =SUMIF(ChuyenDe!$G$3:$G$59, $B11, ChuyenDe!$H$3:$H$59) -> 50.416667 | E11: 0.45 | F11: =E11*$E$5 -> 1138500 | G11: =D11*F11 -> 57399375
A12: 5 | B12: Trần Thanh Ngân | C12: Thành viên chính | D12: =SUMIF(ChuyenDe!$G$3:$G$59, $B12, ChuyenDe!$H$3:$H$59) -> 52.066667 | E12: 0.45 | F12: =E12*$E$5 -> 1138500 | G12: =D12*F12 -> 59277900
D13: =SUM(D8:D12) -> 264.36667 | F13: =AVERAGE(F8:F12) -> 1290300 | G13: =SUM(G8:G12) -> 342865600
B14: Bằng chữ: Ba trăm bốn mươi hai triệu tám trăm sáu mươi lăm nghìn sáu trăm đồng
D16: Hà Nội, Ngày 13 tháng 9 năm 2026
B17: Chủ nhiệm đề tài | D17: Người lập bảng

Sheet ThietBiVatTu
A1: PHỤ LỤC DỰ TOÁN KINH PHÍ 2. Thiết bị vật tư
A2: ĐỀ TÀI | B2: Xây dựng hệ thống quản lý du học sinh bậc đại học của trung tâm tư vấn vấn du học Amec
A3: MÃ SỐ | B3: CNTT20261_N03
A4: CHỦ TRÌ | B4: Bùi Thanh Phương
A5: Thiết bị vật tư phục vụ đề tài
A7: STT | B7: TÊN | C7: ĐƠN VỊ TÍNH | D7: SỐ LƯỢNG | E7: ĐƠN GIÁ (VNĐ) | F7: THÀNH TIỀN (VNĐ)
A8: I | B8: Giai đoạn A (Khảo sát hiện trạng & Thu thập yêu cầu nghiệp vụ)
A9: 1 | B9: Thuê laptop cấu hình cao cho nhân sự onsite | C9: Bộ | D9: 2 | E9: 2450000 | F9: 4900000
A10: II | B10: Giai đoạn B (Phân tích chức năng & Đặc tả Use Case)
A11: 1 | B11: Thuê laptop cấu hình cao cho nhân sự onsite | C11: Bộ | D11: 2 | E11: 2450000 | F11: 4900000
A12: III | B12: Giai đoạn C (Phân tích cấu trúc & Hành vi hệ thống)
A13: 1 | B13: Cloud Server (Môi trường Staging/Dev) | C13: Tháng | D13: 2 | E13: 2380000 | F13: 4760000
A14: 2 | B14: Thuê bộ máy tính onsite | C14: Bộ | D14: 5 | E14: 1750000 | F14: 8750000
A15: IV | B15: Giai đoạn D (Thiết kế kiến trúc, Lớp chi tiết & CSDL)
A16: 1 | B16: Thuê bộ máy tính onsite | C16: Bộ | D16: 5 | E16: 1750000 | F16: 8750000
A17: 2 | B17: Đăng ký tên miền hệ thống (.vn) | C17: Năm | D17: 1 | E17: 850000 | F17: 850000
A18: V | B18: Giai đoạn E (Thiết kế UI/UX & Lập trình mô đun phần mềm)
A19: 1 | B19: Cloud Server (Môi trường Testing/Pre-prod) | C19: Tháng | D19: 2 | E19: 3250000 | F19: 6500000
A20: 2 | B20: Thuê bộ máy tính onsite | C20: Bộ | D20: 5 | E20: 1750000 | F20: 8750000
A21: 3 | B21: Object Storage lưu hồ sơ điện tử (Dev/Test) | C21: Tháng | D21: 2 | E21: 2850000 | F21: 5700000
A22: VI | B22: Giai đoạn F (Kiểm thử, Đào tạo, Bàn giao & Nghiệm thu)
A23: 1 | B23: Thuê bộ máy tính onsite | C23: Bộ | D23: 5 | E23: 1750000 | F23: 8750000
A24: 2 | B24: Object Storage lưu hồ sơ điện tử Production | C24: Tháng | D24: 2 | E24: 6637500 | F24: 13275000
A25: TỔNG CỘNG | F25: 80325000
B27: Bằng chữ:Tám mươi triệu ba trăm hai mươi lăm nghìn đồng
D29: Hà Nội, Ngày 13 tháng 9 năm 2026
B30: Chủ nhiệm đề tài | D30: Người lập bảng

Sheet ChiKhac
A1: PHỤ LỤC DỰ TOÁN KINH PHÍ 3. Chi khác
A2: ĐỀ TÀI | B2: Xây dựng hệ thống quản lý du học sinh bậc đại học của trung tâm tư vấn vấn du học Amec
A3: MÃ SỐ | B3: CNTT20261_N03
A4: CHỦ TRÌ | B4: Bùi Thanh Phương
A5: Chi khác phục vụ đề tài
A7: STT | B7: NỘI DUNG | C7: Mô tả chi tiết | D7: SỐ TIỀN (VNĐ)
A8: Giai đoạn A (Khảo sát hiện trạng, thu thập yêu cầu & mô tả quy trình nghiệp vụ - Tháng 09/2026 - 10/2026)
A9: 1 | B9: Văn phòng phẩm (phô tô, in ấn tài liệu) | C9: In ấn biểu mẫu khảo sát hiện trạng nghiệp vụ, photo tài liệu tài nguyên hệ thống hiện tại của FlyHigh và in tài liệu Tôn chỉ dự án (Project Charter). | D9: 1500000
A10: 2 | B10: Chi phí khảo sát (đi lại, workshop...) | C10: Chi phí di chuyển khảo sát trực tiếp tại các phòng ban FlyHigh, tổ chức workshop phỏng vấn thu thập yêu cầu người dùng (Tuyển sinh, Hồ sơ, Kế toán) và hỗ trợ nước uống họp khảo sát. | D10: 3500000
A11: Giai đoạn B (Phân tích chức năng và đặc tả Use Case hệ thống - Tháng 10/2026 - 11/2026)
A12: 1 | B12: Văn phòng phẩm (phô tô, in ấn tài liệu) | C12: In ấn hồ sơ đặc tả yêu cầu nghiệp vụ (BRD), tài liệu phân tích Use Cases, biểu đồ Usecase tổng quát và phân rã để rà soát với khách hàng. | D12: 2000000
A13: 2 | B13: Chi phí khảo sát (đi lại, workshop...) | C13: Tổ chức 01 buổi Workshop rà soát, thống nhất luồng nghiệp vụ và đặc tả Use Case với Ban Giám đốc và các Trưởng bộ phận của FlyHigh. | D13: 3500000
A14: Giai đoạn C (Phân tích cấu trúc & hành vi hệ thống - Tháng 11/2026 - 12/2026)
A15: 1 | B15: Dịch vụ Email hệ thống | C15: Đăng ký tài khoản Email Server/SMTP API (SendGrid/Mailgun) phục vụ thử nghiệm gửi mã xác thực và mật khẩu ngẫu nhiên cho tính năng quản lý tài khoản. | D15: 350000
A16: 2 | B16: Chi phí phục vụ OT (tiền nước, ăn uống ... cho nhân sự) | C16: Chi phí hỗ trợ ăn uống, nước uống bồi dưỡng cho đội ngũ BA và System Analyst tăng ca (OT) làm việc liên tục để hoàn thiện hệ thống biểu đồ trình tự (Sequence Diagram). | D16: 10000000
A17: Giai đoạn D (Thiết kế các lớp chi tiết & CSDL quan hệ - Tháng 12/2026 - 01/2027)
A18: 1 | B18: Dịch vụ Email hệ thống | C18: Duy trì dịch vụ Email API hệ thống phục vụ việc tích hợp và kiểm thử luồng dữ liệu thông báo qua email trong mô hình CSDL. | D18: 350000
A19: 2 | B19: Chi phí phục vụ OT (tiền nước, ăn uống ... cho nhân sự) | C19: Hỗ trợ chi phí ăn tối, sinh hoạt cho nhân sự thiết kế kiến trúc và CSDL tăng ca (OT) làm việc đêm để chốt mô hình ERD. | D19: 10000000
A20: Giai đoạn E (Thiết kế giao diện UI/UX & Lập trình thử nghiệm - Tháng 01/2027 - 02/2027)
A21: 1 | B21: Dịch vụ Email hệ thống | C21: Tích hợp chính thức Email API vào module phần mềm thử nghiệm phục vụ chức năng gửi email thông báo tự động. | D21: 350000
A22: 2 | B22: Chi phí phục vụ OT (tiền nước, ăn uống ... cho nhân sự) | C22: Bồi dưỡng cho lập trình viên và designer tăng ca (OT) làm việc tập trung để dựng giao diện UI/UX và hoàn thiện tính năng | D22: 10000000
A23: Giai đoạn F (Kiểm thử, đào tạo, bàn giao & nghiệm thu dự án - Tháng 02/2027 - 03/2027)
A24: 1 | B24: Dịch vụ Email hệ thống | C24: Duy trì Email API phục vụ đợt kiểm thử chấp nhận người dùng (UAT) toàn diện và nghiệm thu hệ thống. | D24: 350000
A25: 2 | B25: Chi phí phục vụ OT (tiền nước, ăn uống ... cho nhân sự) | C25: Chi phí hỗ trợ tăng ca cho nhân sự sửa lỗi (Bug fixing) cuối kỳ, đóng gói phần mềm, chuẩn bị tài liệu đào tạo người dùng và lập báo cáo nghiệm thu dự án. | D25: 10000000
A26: TỔNG CỘNG | D26: =sum(D9:D25) -> 51900000
A28: Bằng chữ: Năm mươi triệu chín trăm nghìn đồng
C30: Hà Nội, Ngày 13 tháng 9 năm 2026
B31: Chủ nhiệm đề tài | C31: Người lập bảng
