Workbook
Name _Toc403047574: TonChiDA!$A$27
Name _Toc403047573: TonChiDA!$A$4

Sheet WBS_PhanRaCTCongViec
A1: STT | B1: Task | C1: Mô tả | D1: Sản phẩm | E1: Thời gian | F1: Thứ tự thực hiện | G1: Người thực hiện | H1: Estimate (manday)
H2: MO | I2: ML | J2: MP | K2: EST PERT | L2: Buffer | M2: EST chốt
L3: 0.1
A4: A. KHẢO SÁT & YÊU CẦU
A5: 1 | B5: Khảo sát quy trình tư vấn du học | C5: Khảo sát cách trung tâm tiếp nhận nhu cầu, tư vấn quốc gia, trường, ngành học và theo dõi quá trình tư vấn cho du học sinh. | D5: Báo cáo nghiên cứu | E5: 01/09/2026-25/09/2026 | F5: Từ đầu | G5: Bùi Thanh Phương | H5: 3 | I5: 4 | J5: 6 | K5: =(H5+4*I5+J5)/6 -> 4.1666667 | L5: =K5*$L$3 -> 0.41666667 | M5: =sum(K5:L5) -> 4.5833333
A6: 2 | B6: Khảo sát quy trình tiếp nhận hồ sơ SV | C6: Khảo sát quy trình tiếp nhận, kiểm tra, cập nhật và lưu trữ thông tin hồ sơ của du học sinh. | D6: Báo cáo nghiên cứu | F6: Từ đầu | G6: Bùi Thanh Phương | H6: 3 | I6: 4 | J6: 6 | K6: =(H6+4*I6+J6)/6 -> 4.1666667 | L6: =K6*$L$3 -> 0.41666667 | M6: =sum(K6:L6) -> 4.5833333
A7: 3 | B7: Khảo sát quy trình Visa | C7: Khảo sát quy trình quản lý hồ sơ Visa, tình trạng Visa, thời hạn Visa và quá trình gia hạn Visa cho du học sinh. | D7: Báo cáo nghiên cứu | F7: Từ đầu | G7: Bùi Thanh Phương | H7: 2 | I7: 4 | J7: 6 | K7: =(H7+4*I7+J7)/6 -> 4 | L7: =K7*$L$3 -> 0.4 | M7: =sum(K7:L7) -> 4.4
A8: 4 | B8: Khảo sát học phí, tài chính | C8: Khảo sát cách trung tâm quản lý học phí, hóa đơn, các khoản thanh toán và tình trạng tài chính của du học sinh. | D8: Báo cáo nghiên cứu | F8: Từ đầu | G8: Bùi Thanh Phương | H8: 2 | I8: 3 | J8: 5 | K8: =(H8+4*I8+J8)/6 -> 3.1666667 | L8: =K8*$L$3 -> 0.31666667 | M8: =sum(K8:L8) -> 3.4833333
A9: 5 | B9: Tổng hợp hiện trạng | C9: Tổng hợp kết quả khảo sát, xác định quy trình hiện tại, các vấn đề còn tồn tại và nhu cầu cần giải quyết bằng hệ thống. | D9: Báo cáo nghiên cứu | F9: Sau Task 4 | G9: Bùi Thanh Phương | H9: 3 | I9: 4 | J9: 6 | K9: =(H9+4*I9+J9)/6 -> 4.1666667 | L9: =K9*$L$3 -> 0.41666667 | M9: =sum(K9:L9) -> 4.5833333
A10: 6 | B10: Phân tích yêu cầu hệ thống | C10: Phân tích các yêu cầu chức năng và phi chức năng dựa trên quy trình hoạt động và nhu cầu sử dụng của trung tâm. | D10: Báo cáo nghiên cứu | F10: Sau Task 5 | G10: Trần Thanh Ngân | H10: 4 | I10: 5 | J10: 7 | K10: =(H10+4*I10+J10)/6 -> 5.1666667 | L10: =K10*$L$3 -> 0.51666667 | M10: =sum(K10:L10) -> 5.6833333
A11: 7 | B11: Đặc tả yêu cầu | C11: Chuyển các yêu cầu đã phân tích thành tài liệu đặc tả làm cơ sở cho việc phân tích, thiết kế và xây dựng hệ thống. | D11: Báo cáo nghiên cứu | F11: Sau Task 5 | G11: Trần Thanh Ngân | H11: 3 | I11: 5 | J11: 7 | K11: =(H11+4*I11+J11)/6 -> 5 | L11: =K11*$L$3 -> 0.5 | M11: =sum(K11:L11) -> 5.5
A12: 8 | B12: Xác nhận/chỉnh sửa yêu cầu | C12: Trao đổi với người dùng, tiếp nhận ý kiến phản hồi và điều chỉnh các yêu cầu để bảo đảm phù hợp với nghiệp vụ. | D12: Báo cáo nghiên cứu | F12: Sau Task 7 | G12: Trần Thanh Ngân | H12: 2 | I12: 3 | J12: 5 | K12: =(H12+4*I12+J12)/6 -> 3.1666667 | L12: =K12*$L$3 -> 0.31666667 | M12: =sum(K12:L12) -> 3.4833333
A13: B. PHÂN TÍCH & THIẾT KẾ HỆ THỐNG
A14: 9 | B14: Xác định Actor hệ thống | C14: Xác định các tác nhân tham gia hệ thống như quản trị viên, nhân viên tư vấn và du học sinh. | D14: Biểu đồ Lớp chi tiết, Mô hình ERD & Đặc tả các bảng CSDL | E14: 25/09/2026-24/11/2026 | F14: Sau Task 8 | G14: Bùi Thanh Phương | H14: 2 | I14: 3 | J14: 4 | K14: =(H14+4*I14+J14)/6 -> 3 | L14: =K14*$L$3 -> 0.3 | M14: =sum(K14:L14) -> 3.3
A15: 10 | B15: Xác định Use Case | C15: Xác định các chức năng mà từng Actor được phép thực hiện trên hệ thống quản lý du học sinh. | D15: Biểu đồ Lớp chi tiết, Mô hình ERD & Đặc tả các bảng CSDL | F15: Sau Task 8 | G15: Bùi Thanh Phương | H15: 3 | I15: 4 | J15: 6 | K15: =(H15+4*I15+J15)/6 -> 4.1666667 | L15: =K15*$L$3 -> 0.41666667 | M15: =sum(K15:L15) -> 4.5833333
A16: 11 | B16: Vẽ Use Case tổng quát | C16: Xây dựng biểu đồ Use Case tổng quát thể hiện Actor, các chức năng và mối quan hệ giữa các chức năng của hệ thống. | D16: Biểu đồ Lớp chi tiết, Mô hình ERD & Đặc tả các bảng CSDL | F16: Sau Task 8 | G16: Bùi Thanh Phương | H16: 2 | I16: 3 | J16: 5 | K16: =(H16+4*I16+J16)/6 -> 3.1666667 | L16: =K16*$L$3 -> 0.31666667 | M16: =sum(K16:L16) -> 3.4833333
A17: 12 | B17: Đặc tả Use Case | C17: Mô tả chi tiết luồng chính, luồng thay thế, điều kiện trước/sau và xử lý của từng Use Case. | D17: Biểu đồ Lớp chi tiết, Mô hình ERD & Đặc tả các bảng CSDL | F17: Sau Task 11 | G17: Bùi Thanh Phương | H17: 4 | I17: 6 | J17: 8 | K17: =(H17+4*I17+J17)/6 -> 6 | L17: =K17*$L$3 -> 0.6 | M17: =sum(K17:L17) -> 6.6
A18: 13 | B18: Xác định biểu đồ Class | C18: Xây dựng mô hình lớp gồm các lớp dữ liệu, thuộc tính, phương thức và mối quan hệ phục vụ hệ thống. | D18: Biểu đồ Lớp chi tiết, Mô hình ERD & Đặc tả các bảng CSDL | F18: Sau Task 12 | G18: Trần Thanh Ngân | H18: 4 | I18: 6 | J18: 9 | K18: =(H18+4*I18+J18)/6 -> 6.1666667 | L18: =K18*$L$3 -> 0.61666667 | M18: =sum(K18:L18) -> 6.7833333
A19: 14 | B19: Thiết kế biểu đồ Sequence | C19: Mô hình hóa trình tự tương tác giữa người dùng, giao diện và các thành phần hệ thống khi thực hiện chức năng. | D19: Biểu đồ Lớp chi tiết, Mô hình ERD & Đặc tả các bảng CSDL | F19: Sau Task 12 | G19: Trần Thanh Ngân | H19: 4 | I19: 6 | J19: 9 | K19: =(H19+4*I19+J19)/6 -> 6.1666667 | L19: =K19*$L$3 -> 0.61666667 | M19: =sum(K19:L19) -> 6.7833333
A20: 15 | B20: Thiết kế biểu đồ Activity | C20: Mô tả luồng xử lý và các bước hoạt động của những nghiệp vụ chính trong hệ thống. | D20: Biểu đồ Lớp chi tiết, Mô hình ERD & Đặc tả các bảng CSDL | F20: Sau Task 12 | G20: Trần Thanh Ngân | H20: 4 | I20: 6 | J20: 9 | K20: =(H20+4*I20+J20)/6 -> 6.1666667 | L20: =K20*$L$3 -> 0.61666667 | M20: =sum(K20:L20) -> 6.7833333
A21: 16 | B21: Thiết kế kiến trúc hệ thống | C21: Xác định kiến trúc tổng thể, các tầng xử lý và cách các thành phần của hệ thống tương tác với nhau. | D21: Biểu đồ Lớp chi tiết, Mô hình ERD & Đặc tả các bảng CSDL | F21: Sau Task 12 | G21: Trần Thanh Ngân | H21: 3 | I21: 5 | J21: 7 | K21: =(H21+4*I21+J21)/6 -> 5 | L21: =K21*$L$3 -> 0.5 | M21: =sum(K21:L21) -> 5.5
A22: C. THIẾT KẾ CƠ SỞ DỮ LIỆU & GIAO DIỆN
A23: 17 | B23: Xác định các bảng dữ liệu | C23: Xác định các nhóm dữ liệu cần quản lý như sinh viên, người thân, Visa, trường học, học tập, học bổng và tài chính. | D23: Biểu đồ Lớp chi tiết, Mô hình ERD & Đặc tả các bảng CSDL | E23: 25/11/2026-27/12/2026 | F23: Sau Task 12 | G23: Chu Quang Hiếu | H23: 3 | I23: 4 | J23: 6 | K23: =(H23+4*I23+J23)/6 -> 4.1666667 | L23: =K23*$L$3 -> 0.41666667 | M23: =sum(K23:L23) -> 4.5833333
A24: 18 | B24: Thiết kế ERD | C24: Xây dựng mô hình thực thể – liên kết, xác định khóa và mối quan hệ giữa các đối tượng dữ liệu trong hệ thống. | D24: Biểu đồ Lớp chi tiết, Mô hình ERD & Đặc tả các bảng CSDL | F24: Sau Task 17 | G24: Chu Quang Hiếu | H24: 3 | I24: 5 | J24: 7 | K24: =(H24+4*I24+J24)/6 -> 5 | L24: =K24*$L$3 -> 0.5 | M24: =sum(K24:L24) -> 5.5
A25: 19 | B25: Thiết kế CSDL SQL Server | C25: Thiết kế cấu trúc cơ sở dữ liệu phục vụ việc lưu trữ và quản lý thông tin du học sinh và các nghiệp vụ liên quan. | D25: Biểu đồ Lớp chi tiết, Mô hình ERD & Đặc tả các bảng CSDL | F25: Sau Task 18 | G25: Chu Quang Hiếu | H25: 4 | I25: 6 | J25: 8 | K25: =(H25+4*I25+J25)/6 -> 6 | L25: =K25*$L$3 -> 0.6 | M25: =sum(K25:L25) -> 6.6
A26: 20 | B26: Tạo bảng, khóa, ràng buộc | C26: Xây dựng các bảng dữ liệu, khóa chính, khóa ngoại và các ràng buộc nhằm bảo đảm tính toàn vẹn dữ liệu. | D26: Biểu đồ Lớp chi tiết, Mô hình ERD & Đặc tả các bảng CSDL | F26: Sau Task 19 | G26: Chu Quang Hiếu | H26: 3 | I26: 5 | J26: 7 | K26: =(H26+4*I26+J26)/6 -> 5 | L26: =K26*$L$3 -> 0.5 | M26: =sum(K26:L26) -> 5.5
A27: 21 | B27: Thiết kế giao diện đăng nhập | C27: Thiết kế màn hình đăng nhập, nhập thông tin tài khoản và các thông báo khi đăng nhập không hợp lệ. | D27: Thiết kế UI/UX hệ thống | F27: Sau Task 20 | G27: Lê Linh Hương | H27: 2 | I27: 3 | J27: 4 | K27: =(H27+4*I27+J27)/6 -> 3 | L27: =K27*$L$3 -> 0.3 | M27: =sum(K27:L27) -> 3.3
A28: 22 | B28: Thiết kế giao diện quản lý SV | C28: Thiết kế màn hình thêm, sửa, xóa, xem và tìm kiếm thông tin hồ sơ du học sinh. | D28: Thiết kế UI/UX hệ thống | F28: Sau Task 20 | G28: Lê Linh Hương | H28: 3 | I28: 5 | J28: 7 | K28: =(H28+4*I28+J28)/6 -> 5 | L28: =K28*$L$3 -> 0.5 | M28: =sum(K28:L28) -> 5.5
A29: 23 | B29: Thiết kế giao diện Visa/tài chính | C29: Thiết kế giao diện quản lý thông tin Visa, thời hạn Visa, học phí, hóa đơn và tình trạng thanh toán. | D29: Thiết kế UI/UX hệ thống | F29: Sau Task 20 | G29: Lê Linh Hương | H29: 3 | I29: 5 | J29: 7 | K29: =(H29+4*I29+J29)/6 -> 5 | L29: =K29*$L$3 -> 0.5 | M29: =sum(K29:L29) -> 5.5
A30: 24 | B30: Thiết kế giao diện Dashboard | C30: Thiết kế màn hình tổng quan hiển thị các số liệu thống kê về sinh viên, Visa, tài chính và các thông tin cần theo dõi. | D30: Thiết kế UI/UX hệ thống | F30: Sau Task 20 | G30: Lê Linh Hương | H30: 3 | I30: 4 | J30: 6 | K30: =(H30+4*I30+J30)/6 -> 4.1666667 | L30: =K30*$L$3 -> 0.41666667 | M30: =sum(K30:L30) -> 4.5833333
A31: D. XÂY DỰNG CHƯƠNG TRÌNH
A32: 25 | B32: Đăng nhập & phân quyền | C32: Xây dựng chức năng đăng nhập, xác thực tài khoản và phân quyền truy cập theo vai trò người sử dụng. | D32: Prototype UI/UX 1 số màn hình | E32: 25/12/2026-01/03/2027 | F32: Sau Task 20 | G32: Nguyễn Đức Hậu | H32: 3 | I32: 5 | J32: 7 | K32: =(H32+4*I32+J32)/6 -> 5 | L32: =K32*$L$3 -> 0.5 | M32: =sum(K32:L32) -> 5.5
A33: 26 | B33: Quản lý tài khoản nhân viên | C33: Xây dựng chức năng tạo, cập nhật, khóa/mở khóa và quản lý tài khoản của nhân viên trung tâm. | D33: Prototype UI/UX 1 số màn hình | F33: Sau Task 20 | G33: Nguyễn Đức Hậu | H33: 3 | I33: 4 | J33: 6 | K33: =(H33+4*I33+J33)/6 -> 4.1666667 | L33: =K33*$L$3 -> 0.41666667 | M33: =sum(K33:L33) -> 4.5833333
A34: 27 | B34: Quản lý hồ sơ sinh viên | C34: Xây dựng chức năng thêm, sửa, xóa, xem và quản lý thông tin cá nhân, liên hệ và hồ sơ của du học sinh. | D34: Prototype UI/UX 1 số màn hình | F34: Sau Task 20 | G34: Nguyễn Đức Hậu | H34: 4 | I34: 6 | J34: 9 | K34: =(H34+4*I34+J34)/6 -> 6.1666667 | L34: =K34*$L$3 -> 0.61666667 | M34: =sum(K34:L34) -> 6.7833333
A35: 28 | B35: Quản lý người thân | C35: Xây dựng chức năng lưu trữ và cập nhật thông tin người thân, mối quan hệ và thông tin liên hệ của du học sinh. | D35: Prototype UI/UX 1 số màn hình | F35: Sau Task 20 | G35: Nguyễn Đức Hậu | H35: 3 | I35: 4 | J35: 6 | K35: =(H35+4*I35+J35)/6 -> 4.1666667 | L35: =K35*$L$3 -> 0.41666667 | M35: =sum(K35:L35) -> 4.5833333
A36: 29 | B36: Quản lý Visa | C36: Xây dựng chức năng quản lý hộ chiếu, loại Visa, ngày cấp, ngày hết hạn, tình trạng và kết quả Visa của du học sinh. | D36: Prototype UI/UX 1 số màn hình | F36: Sau Task 20 | G36: Nguyễn Đức Hậu | H36: 4 | I36: 6 | J36: 9 | K36: =(H36+4*I36+J36)/6 -> 6.1666667 | L36: =K36*$L$3 -> 0.61666667 | M36: =sum(K36:L36) -> 6.7833333
A37: 30 | B37: Quản lý trường đại học | C37: Xây dựng chức năng thêm, sửa, xóa và quản lý thông tin các trường đại học, quốc gia và ngành học liên quan. | D37: Prototype UI/UX 1 số màn hình | F37: Sau Task 20 | G37: Nguyễn Đức Hậu | H37: 3 | I37: 5 | J37: 7 | K37: =(H37+4*I37+J37)/6 -> 5 | L37: =K37*$L$3 -> 0.5 | M37: =sum(K37:L37) -> 5.5
A38: 31 | B38: Tìm kiếm sinh viên | C38: Xây dựng chức năng tìm kiếm và tra cứu thông tin du học sinh theo các tiêu chí phù hợp. | D38: Prototype UI/UX 1 số màn hình | F38: Sau Task 20 | G38: Lê Linh Hương | H38: 2 | I38: 3 | J38: 5 | K38: =(H38+4*I38+J38)/6 -> 3.1666667 | L38: =K38*$L$3 -> 0.31666667 | M38: =sum(K38:L38) -> 3.4833333
A39: 32 | B39: Tìm kiếm trường đại học | C39: Xây dựng chức năng tìm kiếm và tra cứu trường đại học theo quốc gia, trường hoặc các thông tin liên quan. | D39: Prototype UI/UX 1 số màn hình | F39: Sau Task 20 | G39: Lê Linh Hương | H39: 2 | I39: 3 | J39: 5 | K39: =(H39+4*I39+J39)/6 -> 3.1666667 | L39: =K39*$L$3 -> 0.31666667 | M39: =sum(K39:L39) -> 3.4833333
A40: 33 | B40: Quản lý hồ sơ học thuật | C40: Xây dựng chức năng quản lý thông tin học tập, chương trình học và kết quả học tập của du học sinh. | D40: Prototype UI/UX 1 số màn hình | F40: Sau Task 20 | G40: Lê Linh Hương | H40: 3 | I40: 5 | J40: 7 | K40: =(H40+4*I40+J40)/6 -> 5 | L40: =K40*$L$3 -> 0.5 | M40: =sum(K40:L40) -> 5.5
...

Sheet TongCongSoMoiThanhVien
A1: Thành viên | B1: Giai đoạn A | C1: Giai đoạn B | D1: Giai đoạn C | E1: Giai đoạn D | F1: Giai đoạn E | G1: Giai đoạn F | H1: Tổng cộng
A2: Bùi Thanh Phương | B2: =SUMIF(WBS_PhanRaCTCongViec!$G$5:$G$12, $A2, WBS_PhanRaCTCongViec!$M$5:$M$12) -> 21.633333 | C2: =SUMIF(WBS_PhanRaCTCongViec!$G$14:$G$21, $A2, WBS_PhanRaCTCongViec!$M$14:$M$21) -> 17.966667 | D2: =SUMIF(WBS_PhanRaCTCongViec!$G$23:$G$30, $A2, WBS_PhanRaCTCongViec!$M$23:$M$30) -> 0 | E2: =SUMIF(WBS_PhanRaCTCongViec!$G$32:$G$44, $A2, WBS_PhanRaCTCongViec!$M$32:$M$44) -> 0 | F2: =SUMIF(WBS_PhanRaCTCongViec!$G$46:$G$53, $A2, WBS_PhanRaCTCongViec!$M$46:$M$55) -> 12.283333 | G2: =SUMIF(WBS_PhanRaCTCongViec!$G$57:$G$61, $A2, WBS_PhanRaCTCongViec!$M$57:$M$61) -> 3.3 | H2: =SUM(B2:G2) -> 55.183333
A3: Nguyễn Đức Hậu | B3: =SUMIF(WBS_PhanRaCTCongViec!$G$5:$G$12, $A3, WBS_PhanRaCTCongViec!$M$5:$M$12) -> 0 | C3: =SUMIF(WBS_PhanRaCTCongViec!$G$14:$G$21, $A3, WBS_PhanRaCTCongViec!$M$14:$M$21) -> 0 | D3: =SUMIF(WBS_PhanRaCTCongViec!$G$23:$G$30, $A3, WBS_PhanRaCTCongViec!$M$23:$M$30) -> 0 | E3: =SUMIF(WBS_PhanRaCTCongViec!$G$32:$G$44, $A3, WBS_PhanRaCTCongViec!$M$32:$M$44) -> 33.733333 | F3: =SUMIF(WBS_PhanRaCTCongViec!$G$46:$G$53, $A3, WBS_PhanRaCTCongViec!$M$46:$M$55) -> 16.866667 | G3: =SUMIF(WBS_PhanRaCTCongViec!$G$57:$G$61, $A3, WBS_PhanRaCTCongViec!$M$57:$M$61) -> 3.3 | H3: =SUM(B3:G3) -> 53.9
A4: Lê Linh Hương | B4: =SUMIF(WBS_PhanRaCTCongViec!$G$5:$G$12, $A4, WBS_PhanRaCTCongViec!$M$5:$M$12) -> 0 | C4: =SUMIF(WBS_PhanRaCTCongViec!$G$14:$G$21, $A4, WBS_PhanRaCTCongViec!$M$14:$M$21) -> 0 | D4: =SUMIF(WBS_PhanRaCTCongViec!$G$23:$G$30, $A4, WBS_PhanRaCTCongViec!$M$23:$M$30) -> 18.883333 | E4: =SUMIF(WBS_PhanRaCTCongViec!$G$32:$G$44, $A4, WBS_PhanRaCTCongViec!$M$32:$M$44) -> 17.05 | F4: =SUMIF(WBS_PhanRaCTCongViec!$G$46:$G$55, $A4, WBS_PhanRaCTCongViec!$M$46:$M$55) -> 16.866667 | G4: =SUMIF(WBS_PhanRaCTCongViec!$G$57:$G$61, $A4, WBS_PhanRaCTCongViec!$M$57:$M$61) -> 0 | H4: =SUM(B4:G4) -> 52.8
A5: Chu Quang Hiếu | B5: =SUMIF(WBS_PhanRaCTCongViec!$G$5:$G$12, $A5, WBS_PhanRaCTCongViec!$M$5:$M$12) -> 0 | C5: =SUMIF(WBS_PhanRaCTCongViec!$G$14:$G$21, $A5, WBS_PhanRaCTCongViec!$M$14:$M$21) -> 0 | D5: =SUMIF(WBS_PhanRaCTCongViec!$G$23:$G$30, $A5, WBS_PhanRaCTCongViec!$M$23:$M$30) -> 22.183333 | E5: =SUMIF(WBS_PhanRaCTCongViec!$G$32:$G$44, $A5, WBS_PhanRaCTCongViec!$M$32:$M$44) -> 17.966667 | F5: =SUMIF(WBS_PhanRaCTCongViec!$G$46:$G$55, $A5, WBS_PhanRaCTCongViec!$M$46:$M$55) -> 6.7833333 | G5: =SUMIF(WBS_PhanRaCTCongViec!$G$57:$G$61, $A5, WBS_PhanRaCTCongViec!$M$57:$M$61) -> 3.4833333 | H5: =SUM(B5:G5) -> 50.416667
A6: Trần Thanh Ngân | B6: =SUMIF(WBS_PhanRaCTCongViec!$G$5:$G$12, $A6, WBS_PhanRaCTCongViec!$M$5:$M$12) -> 14.666667 | C6: =SUMIF(WBS_PhanRaCTCongViec!$G$14:$G$21, $A6, WBS_PhanRaCTCongViec!$M$14:$M$21) -> 25.85 | D6: =SUMIF(WBS_PhanRaCTCongViec!$G$23:$G$30, $A6, WBS_PhanRaCTCongViec!$M$23:$M$30) -> 0 | E6: =SUMIF(WBS_PhanRaCTCongViec!$G$32:$G$44, $A6, WBS_PhanRaCTCongViec!$M$32:$M$44) -> 0 | F6: =SUMIF(WBS_PhanRaCTCongViec!$G$46:$G$55, $A6, WBS_PhanRaCTCongViec!$M$46:$M$55) -> 3.4833333 | G6: =SUMIF(WBS_PhanRaCTCongViec!$G$57:$G$61, $A6, WBS_PhanRaCTCongViec!$M$57:$M$61) -> 8.0666667 | H6: =SUM(B6:G6) -> 52.066667

Sheet TonChiDA
A1: PHẦN 2 : TÔN CHỈ DỰ ÁN
A2: Tôn chỉ dự án (Project Charter)
A4: 1. Mô tả dự án
A5: • Tên dự án: Xây dựng hệ thống quản lý du học sinh bậc đại học của trung tâm tư vấn vấn du học Amec
A6: • Ngày bẳt đầu: 01/09/2026
A7: • Ngày kết thúc: 31/03/2027
A8: • Chủ đầu tư: Trung tâm tư vấn vấn du học Amec
A9: • Kinh phí: 1.000.000.000 VND (Một tỷ đồng)
A10: • Giám đốc dự án: Bùi Thanh Phương
A11: • Mục tiêu dự án: - Mục tiêu tổng quát: Xây dựng thành công Hệ thống phần mềm quản lý du học sinh bậc đại học cho trung tâm tư vấn du học Amec, tối ưu hóa toàn bộ các công đoạn quản lý từ khâu tiếp nhận đến sau khi du học. - Mục tiêu cụ thể: + Số hóa và chuẩn hóa 10 quy trình nghiệp vụ cốt lõi: Tiếp nhận hồ sơ, Tư vấn chọn trường, Quản lý Visa/pháp lý, Quản lý Học bổng, Quản lý Tài chính, Cập nhật GPA, Quản lý Người thân, Hỗ trợ du học sinh, Báo cáo thống kê, + Quản lý Trường đối tác một cách khoa học, trật tự nhằm nâng cao hiệu suất và chất lượng công việc của trung tâm. + Phân tích & thiết kế chi tiết hệ thống sao cho phù hợp với nhu cầu và workflow thực tế của trung tâm. + Xây dựng CSDL chuẩn hóa, đảm bảo các dữ liệu được tổ chức lưu phù hợp, bảo mật an toàn thông tin.
A12: - Chức năng nghiệp vụ : Hệ thống cung cấp chức năng để phục vụ cho các hoạt động chính của trung tâm: + Tiếp nhận & Tạo hồ sơ du học sinh: Thu thập thông tin cá nhân, kiểm tra tính hợp lệ, tự động cấp mã sinh viên (MSSV) và tạo tài khoản đăng nhập. + Tư vấn ngành & Chọn trường: Đánh giá năng lực/mục tiêu của sinh viên, tra cứu danh sách trường đối tác theo quốc gia và lập hồ sơ định hướng học thuật. + Quản lý Visa & Hồ sơ pháp lý: Lưu trữ thông tin hộ chiếu, theo dõi tiến độ/trạng thái xin visa và tự động cảnh báo lịch gia hạn visa. + Quản lý & Hỗ trợ xin học bổng: Quản lý danh mục học bổng, lọc sinh viên đủ điều kiện, hỗ trợ nộp hồ sơ và ghi nhận kết quả/giá trị học bổng. + Giám sát tài chính & Đối soát học phí: Quản lý thông báo học phí (Invoice), đối chiếu biên lai đóng tiền để kích hoạt hồ sơ visa và đối soát hoa hồng đại lý. + Theo dõi kết quả học tập (GPA): Lưu trữ bảng điểm GPA, tổng tín chỉ tích lũy từng kỳ và tự động gợi ý xếp loại học lực. + Quản lý thông tin người thân: Lưu trữ chi tiết thông tin liên hệ của người bảo lãnh/người thân để sử dụng trong trường hợp khẩn cấp. + Hỗ trợ du học sinh tại nước ngoài: Tiếp nhận yêu cầu trợ giúp (học tập, đời sống, pháp lý) và phối hợp với trường đối tác để xử lý. + Thống kê & Báo cáo quản trị: Xuất báo cáo tự động và hiển thị Dashboard về tỷ lệ visa, doanh thu, công nợ học phí và phân bổ thị trường. + Quản lý danh mục trường đối tác: Cập nhật thông tin chi tiết, xếp hạng, ngành học và chính sách tuyển sinh/học phí của các trường liên kết.
A13: - Yêu cầu kĩ thuật (Đáp ứng được tiêu chuẩn của một Website): + Kiến trúc & Công nghệ: Xây dựng theo mô hình 3 lớp (MVC (Model-View-Controller)). + Giao diện hiển thị tốt trên PC. + Cơ sở dữ liệu: Thiết kế CSDL quan hệ chuẩn hóa (SQL Server/MySQL) + Hiệu năng & Khả năng mở rộng: Thời gian phản hồi truy vấn dữ liệu/tìm kiếm dưới 2 giây; sẵn sàng tích hợp API mở rộng (Email/SMS Automation, Payment Gateway). + Bảo mật: Mã hóa mật khẩu người dùng, cơ chế phân quyền RBAC (Role-Based Access Control) nghiêm ngặt, đảm bảo an toàn dữ liệu cá nhân theo quy định.
... A17: - Đối tượng sử dụng: Vai trò và trách nhiệm.
A18: Vai trò | B18: Họ tên | C18: Tổ chức/vị trí | D18: Liên hệ
C19: Organization/Position | D19: Contact Information
A20: Khách hàng | B20: Ban Giám Đốc | C20: Trung tâm tư vấn du học Amec | D20: contact@amec.edu.vn
A21: Người sử dụng | B21: Nhân viên & Sinh viên | C21: Trung tâm Amec (Tuyển sinh, Hồ sơ, Kế toán) & Du học sinh | D21: support@amec.edu.vn
A22: Giám đốc dự án | B22: Bùi Thanh Phương | C22: Trường CNTT&TT - ĐHBK Hà Nội / Giám đốc Dự án | D22: phuong.bt240076@sis.hust.edu.vn
A23: Trưởng nhóm Kỹ thuật (Tech Lead) | B23: Nguyễn Đức Hậu | C23: Trường CNTT&TT - ĐHBK Hà Nội / Giám đốc Dự án | D23: hau.nd240049@sis.hust.edu.vn
A24: Ký tên
A27: 2. Công bố dự án
A28: Quyết định khởi công dự án phần mềm
A29: (Số 03 Ngày 31/07/2026)
A30: Tên dự án | B30: Xây dựng hệ thống quản lý du học sinh bậc đại học của trung tâm tư vấn du học Amec
A31: Mã số | B31: CNTT20261_N03
A32: Chủ đấu tư | B32: Trung tâm tư vấn du học Amec
A33: Thời gian | B33: 06 tháng (Từ 01/09/2026 đến 31/03/2027)
A34: Giám đốc dự án | B34: Bùi Thanh Phương
A35: Quản trị viên | B35: Bùi Thanh Phương
A36: Qui mô dự án | B36: Dự án phần mềm quy mô vừa, ngân sách 1.000.000.000 VNĐ Gồm 5 thành viên cốt cán đảm nhận các công việc từ khảo sát, phân tích thiết kế, đến phát triển và kiểm thử.
A37: Mục tiêu và các yêu cầu | B37: Xây dựng hệ thống web-app quản lý tập trung các quy trình nghiệp vụ du học sinh; đáp ứng đầy đủ các tiêu chuẩn kỹ thuật MVC, bảo mật CSDL, bàn giao đúng hạn ngày 31/03/2027 và tuân thủ ngân sách phê duyệt.
C39: Giám đốc dự án
C40: (Ký và ghi rõ tên)
