Workbook

Sheet CÔNG VIỆC
A1: BẢNG KINH PHÍ CÔNG VIỆC (WORK COST BREAKDOWN) HỆ THỐNG QUẢN LÝ VÀ KẾT NỐI DỮ LIỆU DỰ ÁN XÂY DỰNG
A3: Mã số đề tài: CNTT20261_N10 | Học phần: Quản trị dự án CNTT - Nhóm 10 | Trường Công nghệ Thông tin và Truyền thông - ĐHBK Hà Nội
A4: Kinh phí công lao động theo 55 gói công việc WBS thuộc 06 giai đoạn. Định mức/ngày công tra tự động từ sheet CongLaoDong bằng hàm VLOOKUP.
A6: TT | B6: Các nội dung, công việc thực hiện (WBS) | C6: Sản phẩm bàn giao | D6: Thời gian thực hiện | E6: Giai đoạn / Nhóm quy trình | F6: Chức danh | G6: Người thực hiện | H6: Số ngày công | I6: Định mức (đ/ngày công) | J6: Thành tiền (đ)
A8: 1 | B8: WBS-01. Khảo sát hiện trạng | C8: Báo cáo phân tích hiện trạng Khảo sát hiện trạng | D8: 10/09/2026 - 30/09/2026 | E8: Giai đoạn I | F8: Thư ký | G8: Trần Tiến Thạnh | H8: 14.5 | I8: =VLOOKUP(G8,'CÔNG LAO ĐỘNG'!$B$9:$G$14,5,0) -> 1265000 | J8: =H8*I8 -> 18342500
A9: 2 | B9: WBS-02. Hợp nhất hiện trạng | C9: Báo cáo phân tích hiện trạng Hợp nhất hiện trạng | D9: 10/09/2026 - 30/09/2026 | E9: Giai đoạn I | F9: Thư ký | G9: Trần Tiến Thạnh | H9: 9 | I9: =VLOOKUP(G9,'CÔNG LAO ĐỘNG'!$B$9:$G$14,5,0) -> 1265000 | J9: =H9*I9 -> 11385000
A10: 3 | B10: WBS-03. Phân tích hiện trạng | C10: Báo cáo phân tích hiện trạng Phân tích hiện trạng | D10: 10/09/2026 - 30/09/2026 | E10: Giai đoạn I | F10: Thư ký | G10: Trần Tiến Thạnh | H10: 10 | I10: =VLOOKUP(G10,'CÔNG LAO ĐỘNG'!$B$9:$G$14,5,0) -> 1265000 | J10: =H10*I10 -> 12650000
A11: 4 | B11: WBS-04. Đưa ra báo cáo đặc tả yêu cầu | C11: Tài liệu Đặc tả yêu cầu phần mềm (SRS) v1.0 | D11: 10/09/2026 - 30/09/2026 | E11: Giai đoạn I | F11: Thư ký | G11: Trần Tiến Thạnh | H11: 14.5 | I11: =VLOOKUP(G11,'CÔNG LAO ĐỘNG'!$B$9:$G$14,5,0) -> 1265000 | J11: =H11*I11 -> 18342500
A12: 5 | B12: WBS-05. Mời khách hàng tham vấn | C12: Tài liệu SRS hoàn thiện có xác nhận phê duyệt | D12: 10/09/2026 - 30/09/2026 | E12: Giai đoạn I | F12: Chủ nhiệm | G12: Nguyễn Quốc Hội | H12: 4.5 | I12: =VLOOKUP(G12,'CÔNG LAO ĐỘNG'!$B$9:$G$14,5,0) -> 2024000 | J12: =H12*I12 -> 9108000
A13: 6 | B13: WBS-06. Chỉnh sửa lại yêu cầu phần mềm | C13: Tài liệu SRS hoàn thiện có xác nhận phê duyệt | D13: 10/09/2026 - 30/09/2026 | E13: Giai đoạn I | F13: Thư ký | G13: Trần Tiến Thạnh | H13: 9 | I13: =VLOOKUP(G13,'CÔNG LAO ĐỘNG'!$B$9:$G$14,5,0) -> 1265000 | J13: =H13*I13 -> 11385000
A14: 7 | B14: WBS-07. Xác định ma trận yêu cầu | C14: Ma trận truy vết yêu cầu (RTM) | D14: 01/10/2026 - 22/10/2026 | E14: Giai đoạn II | F14: Thành viên chính | G14: Phạm Đức Hiếu | H14: 9.5 | I14: =VLOOKUP(G14,'CÔNG LAO ĐỘNG'!$B$9:$G$14,5,0) -> 1012000 | J14: =H14*I14 -> 9614000
A15: 8 | B15: WBS-08. Thiết kế kiến trúc hệ thống | C15: Tài liệu Thiết kế kiến trúc tổng quan (SAD) | D15: 01/10/2026 - 22/10/2026 | E15: Giai đoạn II | F15: Thành viên chính | G15: Phạm Đức Hiếu | H15: 16 | I15: =VLOOKUP(G15,'CÔNG LAO ĐỘNG'!$B$9:$G$14,5,0) -> 1012000 | J15: =H15*I15 -> 16192000
A16: 9 | B16: WBS-09. Xác định và phân tích Actor của hệ thống | C16: Sơ đồ và tài liệu Xác định và phân tích Actor của hệ thống | D16: 01/10/2026 - 22/10/2026 | E16: Giai đoạn II | F16: Thành viên chính | G16: Phạm Đức Hiếu | H16: 9.5 | I16: =VLOOKUP(G16,'CÔNG LAO ĐỘNG'!$B$9:$G$14,5,0) -> 1012000 | J16: =H16*I16 -> 9614000
A17: 10 | B17: WBS-10. Xác định và phân tích các User Case | C17: Sơ đồ và tài liệu Xác định và phân tích các User Case | D17: 01/10/2026 - 22/10/2026 | E17: Giai đoạn II | F17: Thành viên chính | G17: Phạm Đức Hiếu | H17: 14 | I17: =VLOOKUP(G17,'CÔNG LAO ĐỘNG'!$B$9:$G$14,5,0) -> 1012000 | J17: =H17*I17 -> 14168000
A18: 11 | B18: WBS-11. Vẽ biểu đồ User Case tổng quát | C18: Sơ đồ và tài liệu Vẽ biểu đồ User Case tổng quát | D18: 01/10/2026 - 22/10/2026 | E18: Giai đoạn II | F18: Thành viên chính | G18: Phạm Đức Hiếu | H18: 9.5 | I18: =VLOOKUP(G18,'CÔNG LAO ĐỘNG'!$B$9:$G$14,5,0) -> 1012000 | J18: =H18*I18 -> 9614000
A19: 12 | B19: WBS-12. User Case đăng nhập & phân quyền | C19: Tài liệu đặc tả chi tiết User Case đăng nhập & phân quyền | D19: 01/10/2026 - 22/10/2026 | E19: Giai đoạn II | F19: Thành viên | G19: Nguyễn Quốc Công | H19: 7 | I19: =VLOOKUP(G19,'CÔNG LAO ĐỘNG'!$B$9:$G$14,5,0) -> 759000 | J19: =H19*I19 -> 5313000
... A40: 33 | B40: WBS-33. Mời khách hàng tham vấn giao diện | C40: Bản thiết kế Prototype UI/UX Figma (Mời khách hàng tham vấn giao diện) | D40: 23/10/2026 - 06/11/2026 | E40: Giai đoạn III | F40: Thành viên chính | G40: Trần Ngọc Đức | H40: 2 | I40: =VLOOKUP(G40,'CÔNG LAO ĐỘNG'!$B$9:$G$14,5,0) -> 1012000 | J40: =H40*I40 -> 2024000
B41: WBS-33. Mời khách hàng tham vấn giao diện (phối hợp) | C41: Bản thiết kế Prototype UI/UX Figma (Mời khách hàng tham vấn giao diện) | D41: 23/10/2026 - 06/11/2026 | E41: Giai đoạn III | F41: Chủ nhiệm | G41: Nguyễn Quốc Hội | H41: 2.5 | I41: =VLOOKUP(G41,'CÔNG LAO ĐỘNG'!$B$9:$G$14,5,0) -> 2024000 | J41: =H41*I41 -> 5060000
A42: 34 | B42: WBS-34. Chỉnh sửa theo yêu cầu | C42: Bản thiết kế Prototype UI/UX Figma (Chỉnh sửa theo yêu cầu) | D42: 23/10/2026 - 06/11/2026 | E42: Giai đoạn III | F42: Thành viên chính | G42: Trần Ngọc Đức | H42: 7.5 | I42: =VLOOKUP(G42,'CÔNG LAO ĐỘNG'!$B$9:$G$14,5,0) -> 1012000 | J42: =H42*I42 -> 7590000
A43: 35 | B43: WBS-35. Thiết kế CSDL | C43: Kịch bản tạo bảng CSDL SQL & Schema ORM | D43: 09/11/2026 - 30/11/2026 | E43: Giai đoạn IV | F43: Thư ký | G43: Trần Tiến Thạnh | H43: 14.5 | I43: =VLOOKUP(G43,'CÔNG LAO ĐỘNG'!$B$9:$G$14,5,0) -> 1265000 | J43: =H43*I43 -> 18342500
A44: 36 | B44: WBS-36. Xây dựng module tầng Data Access | C44: Source code module Xây dựng module tầng Data Access kèm Unit Test | D44: 09/11/2026 - 30/11/2026 | E44: Giai đoạn IV | F44: Thành viên | G44: Nguyễn Thành An | H44: 16.5 | I44: =VLOOKUP(G44,'CÔNG LAO ĐỘNG'!$B$9:$G$14,5,0) -> 759000 | J44: =H44*I44 -> 12523500
A45: 37 | B45: WBS-37. Xây dựng module tầng ADO/Business Service | C45: Source code module Xây dựng module tầng ADO/Business Service kèm Unit Test | D45: 09/11/2026 - 30/11/2026 | E45: Giai đoạn IV | F45: Thành viên | G45: Nguyễn Thành An | H45: 21 | I45: =VLOOKUP(G45,'CÔNG LAO ĐỘNG'!$B$9:$G$14,5,0) -> 759000 | J45: =H45*I45 -> 15939000
A46: 38 | B46: WBS-38. Xây dựng các chức năng phần Quản trị | C46: API & Giao diện phân hệ Quản trị hệ thống | D46: 09/11/2026 - 30/11/2026 | E46: Giai đoạn IV | F46: Thành viên | G46: Nguyễn Thành An | H46: 17.5 | I46: =VLOOKUP(G46,'CÔNG LAO ĐỘNG'!$B$9:$G$14,5,0) -> 759000 | J46: =H46*I46 -> 13282500
A47: 39 | B47: WBS-39. Đăng nhập | C47: Module hoàn thiện chức năng Đăng nhập | D47: 09/11/2026 - 30/11/2026 | E47: Giai đoạn IV | F47: Thành viên | G47: Nguyễn Thành An | H47: 11 | I47: =VLOOKUP(G47,'CÔNG LAO ĐỘNG'!$B$9:$G$14,5,0) -> 759000 | J47: =H47*I47 -> 8349000
A48: 40 | B48: WBS-40. Quản trị danh mục | C48: Module hoàn thiện chức năng Quản trị danh mục | D48: 09/11/2026 - 30/11/2026 | E48: Giai đoạn IV | F48: Thành viên chính | G48: Trần Ngọc Đức | H48: 11 | I48: =VLOOKUP(G48,'CÔNG LAO ĐỘNG'!$B$9:$G$14,5,0) -> 1012000 | J48: =H48*I48 -> 11132000
A49: 41 | B49: WBS-41. Quản lý tiếp nhận & hiển thị BIM | C49: Module hoàn thiện chức năng Quản lý tiếp nhận & hiển thị BIM | D49: 09/11/2026 - 30/11/2026 | E49: Giai đoạn IV | F49: Thành viên chính | G49: Trần Ngọc Đức | H49: 26.5 | I49: =VLOOKUP(G49,'CÔNG LAO ĐỘNG'!$B$9:$G$14,5,0) -> 1012000 | J49: =H49*I49 -> 26818000
A50: 42 | B50: WBS-42. Quản lý quá trình xử lý biểu mẫu | C50: Module hoàn thiện chức năng Quản lý quá trình xử lý biểu mẫu | D50: 09/11/2026 - 30/11/2026 | E50: Giai đoạn IV | F50: Thành viên chính | G50: Trần Ngọc Đức | H50: 9 | I50: =VLOOKUP(G50,'CÔNG LAO ĐỘNG'!$B$9:$G$14,5,0) -> 1012000 | J50: =H50*I50 -> 9108000
B51: WBS-42. Quản lý quá trình xử lý biểu mẫu (phối hợp) | C51: Module hoàn thiện chức năng Quản lý quá trình xử lý biểu mẫu | D51: 09/11/2026 - 30/11/2026 | E51: Giai đoạn IV | F51: Thành viên | G51: Nguyễn Thành An | H51: 13.5 | I51: =VLOOKUP(G51,'CÔNG LAO ĐỘNG'!$B$9:$G$14,5,0) -> 759000 | J51: =H51*I51 -> 10246500
A52: 43 | B52: WBS-43. Hoạt động tìm kiếm | C52: Module hoàn thiện chức năng Hoạt động tìm kiếm | D52: 09/11/2026 - 30/11/2026 | E52: Giai đoạn IV | F52: Thành viên chính | G52: Trần Ngọc Đức | H52: 7.5 | I52: =VLOOKUP(G52,'CÔNG LAO ĐỘNG'!$B$9:$G$14,5,0) -> 1012000 | J52: =H52*I52 -> 7590000
A53: 44 | B53: WBS-44. Chức năng thống kê báo cáo | C53: Module hoàn thiện chức năng Chức năng thống kê báo cáo | D53: 09/11/2026 - 30/11/2026 | E53: Giai đoạn IV | F53: Thành viên | G53: Nguyễn Thành An | H53: 10.5 | I53: =VLOOKUP(G53,'CÔNG LAO ĐỘNG'!$B$9:$G$14,5,0) -> 759000 | J53: =H53*I53 -> 7969500
B54: WBS-44. Chức năng thống kê báo cáo (phối hợp) | C54: Module hoàn thiện chức năng Chức năng thống kê báo cáo | D54: 09/11/2026 - 30/11/2026 | E54: Giai đoạn IV | F54: Thành viên chính | G54: Trần Ngọc Đức | H54: 7 | I54: =VLOOKUP(G54,'CÔNG LAO ĐỘNG'!$B$9:$G$14,5,0) -> 1012000 | J54: =H54*I54 -> 7084000
A55: 45 | B55: WBS-45. Chức năng cho các bên xem kết quả | C55: Module hoàn thiện chức năng Chức năng cho các bên xem kết quả | D55: 09/11/2026 - 30/11/2026 | E55: Giai đoạn IV | F55: Thành viên chính | G55: Trần Ngọc Đức | H55: 11 | I55: =VLOOKUP(G55,'CÔNG LAO ĐỘNG'!$B$9:$G$14,5,0) -> 1012000 | J55: =H55*I55 -> 11132000
A56: 46 | B56: WBS-46. Viết hướng dẫn sử dụng | C56: Bộ tài liệu Hướng dẫn sử dụng chi tiết (User Manual) | D56: 09/11/2026 - 30/11/2026 | E56: Giai đoạn IV | F56: Thành viên | G56: Nguyễn Quốc Công | H56: 7 | I56: =VLOOKUP(G56,'CÔNG LAO ĐỘNG'!$B$9:$G$14,5,0) -> 759000 | J56: =H56*I56 -> 5313000
A57: 47 | B57: WBS-47. Kiểm thử các chức năng phần quản trị | C57: Biên bản kiểm thử và log lỗi (Kiểm thử các chức năng phần quản trị) | D57: 01/12/2026 - 14/12/2026 | E57: Giai đoạn V | F57: Thành viên chính | G57: Phạm Đức Hiếu | H57: 9.5 | I57: =VLOOKUP(G57,'CÔNG LAO ĐỘNG'!$B$9:$G$14,5,0) -> 1012000 | J57: =H57*I57 -> 9614000
A58: 48 | B58: WBS-48. Kiểm thử chức năng phần người dùng | C58: Biên bản kiểm thử và log lỗi (Kiểm thử chức năng phần người dùng) | D58: 01/12/2026 - 14/12/2026 | E58: Giai đoạn V | F58: Thành viên chính | G58: Phạm Đức Hiếu | H58: 15 | I58: =VLOOKUP(G58,'CÔNG LAO ĐỘNG'!$B$9:$G$14,5,0) -> 1012000 | J58: =H58*I58 -> 15180000
A59: 49 | B59: WBS-49. Kiểm thử toàn cục | C59: Biên bản kiểm thử và log lỗi (Kiểm thử toàn cục) | D59: 01/12/2026 - 14/12/2026 | E59: Giai đoạn V | F59: Thành viên chính | G59: Phạm Đức Hiếu | H59: 9 | I59: =VLOOKUP(G59,'CÔNG LAO ĐỘNG'!$B$9:$G$14,5,0) -> 1012000 | J59: =H59*I59 -> 9108000
B60: WBS-49. Kiểm thử toàn cục (phối hợp) | C60: Biên bản kiểm thử và log lỗi (Kiểm thử toàn cục) | D60: 01/12/2026 - 14/12/2026 | E60: Giai đoạn V | F60: Thành viên | G60: Nguyễn Quốc Công | H60: 6.5 | I60: =VLOOKUP(G60,'CÔNG LAO ĐỘNG'!$B$9:$G$14,5,0) -> 759000 | J60: =H60*I60 -> 4933500
A61: 50 | B61: WBS-50. Sửa lỗi chương trình | C61: Biên bản kiểm thử và log lỗi (Sửa lỗi chương trình) | D61: 01/12/2026 - 14/12/2026 | E61: Giai đoạn V | F61: Thành viên | G61: Nguyễn Thành An | H61: 8 | I61: =VLOOKUP(G61,'CÔNG LAO ĐỘNG'!$B$9:$G$14,5,0) -> 759000 | J61: =H61*I61 -> 6072000
B62: WBS-50. Sửa lỗi chương trình (phối hợp) | C62: Biên bản kiểm thử và log lỗi (Sửa lỗi chương trình) | D62: 01/12/2026 - 14/12/2026 | E62: Giai đoạn V | F62: Thành viên chính | G62: Trần Ngọc Đức | H62: 5.5 | I62: =VLOOKUP(G62,'CÔNG LAO ĐỘNG'!$B$9:$G$14,5,0) -> 1012000 | J62: =H62*I62 -> 5566000
A63: 51 | B63: WBS-51. Triển khai trong mạng nội bộ | C63: Môi trường triển khai Staging/Cloud vận hành ổn định | D63: 15/12/2026 - 10/03/2027 | E63: Giai đoạn VI | F63: Thành viên chính | G63: Phạm Đức Hiếu | H63: 8.5 | I63: =VLOOKUP(G63,'CÔNG LAO ĐỘNG'!$B$9:$G$14,5,0) -> 1012000 | J63: =H63*I63 -> 8602000
...

Sheet DỰ TOÁN
A1: BẢNG DỰ TOÁN KINH PHÍ TỔNG THỂ ĐỀ TÀI
A3: ĐỀ TÀI | B3: Quản lý dự án: Xây dựng hệ thống quản lý và kết nối dữ liệu dự án xây dựng
A4: MÃ SỐ | B4: CNTT20261_N10
A5: CHỦ TRÌ | B5: Nguyễn Quốc Hội
A6: THỜI GIAN | B6: 06 tháng, từ 10/09/2026 đến 10/03/2027
A8: TT | B8: Danh mục kinh phí | C8: Số tiền (đ) | D8: Ghi chú giải trình
A9: 1 | B9: Công lao động khoa học (thuê khoán chuyên môn) | C9: ='CÔNG LAO ĐỘNG'!G15 -> 666528500 | D9: Chi tiết tại sheet CongLaoDong và CongViec; tổng hợp từ 55 gói công việc WBS của 06 thành viên.
A10: 2 | B10: Vật tư, thiết bị (hạ tầng cloud, máy chủ và bản quyền) | C10: ='THIẾT BỊ VẬT TỰ'!F22 -> 390000000 | D10: Chi tiết tại sheet Thiết bị vật tư; phân bổ theo 03 giai đoạn triển khai dự án.
A11: 3 | B11: Chi khác (khảo sát, hội thảo, nghiệm thu, VPP, quản lý, dự phòng) | C11: ='CHI PHÍ KHÁC'!D21 -> 72000000 | D11: Chi tiết tại sheet Chi khác; gồm chi phí quản lý cơ quan và quỹ dự phòng tự cân đối.
B12: TỔNG CỘNG | C12: =SUM(C9:C11) -> 1128528500 | D12: Bằng chữ: Một tỷ một trăm hai mươi tám triệu năm trăm hai mươi tám nghìn năm trăm đồng chẵn.
A14: ĐỐI CHIẾU VỚI TÔN CHỈ DỰ ÁN (COST BASELINE)
A15: TT | B15: Chỉ tiêu kiểm soát | C15: Giá trị (đ) | D15: Ghi chú kiểm toán
A16: 1 | B16: Tổng kinh phí được duyệt theo Tôn chỉ dự án | C16: ='CHI PHÍ KHÁC'!$D$6 -> 1128528500 | D16: Ô nhập liệu gốc đặt tại sheet Chi khác, ô D5 (1.128.528.500 đ).
A17: 2 | B17: Chênh lệch Tổng dự toán − Tổng được duyệt | C17: =C12-C16 -> 0 | D17: Phải bằng 0; dòng Quỹ dự phòng tại sheet Chi khác tự cân đối.
A18: 3 | B18: Chỉ tiêu thuê khoán chuyên môn (59.06% tổng kinh phí) | C18: 666528500 | D18: Giữ đúng tỷ trọng 59.06% tổng kinh phí theo Tôn chỉ dự án và thuyết minh.
A19: 4 | B19: Chênh lệch Công lao động so với chỉ tiêu | C19: =C9-C18 -> 0 | D19: Phải bằng 0; khớp hoàn toàn với bảng phân công lao động WBS.
A20: 5 | B20: Tỷ lệ sai lệch Công lao động | C20: =IF(C18=0,0,C19/C18) -> 0 | D20: Ngưỡng kiểm soát theo Tôn chỉ dự án: không vượt quá ±10% (đạt 0.00%).
D22: Hà Nội, ngày 10 tháng 09 năm 2026
B23: GIẢNG VIÊN HƯỚNG DẪN | D23: CHỦ NHIỆM DỰ ÁN
B27: ThS. Lê Thị Hoa | D27: Nguyễn Quốc Hội

Sheet CÔNG LAO ĐỘNG
A1: PHỤ LỤC 1 - DỰ TOÁN KINH PHÍ CÔNG LAO ĐỘNG KHOA HỌC (KHOÁN CHI)
A3: ĐỀ TÀI | B3: Quản lý dự án: Xây dựng hệ thống quản lý và kết nối dữ liệu dự án xây dựng
A4: MÃ SỐ | B4: CNTT20261_N10
A5: CHỦ TRÌ | B5: Nguyễn Quốc Hội
A6: Mức khoán ngày công cơ sở (đồng/ngày công chuẩn): | E6: 2530000
A8: TT | B8: Họ và tên | C8: Nhiệm vụ trong dự án | D8: Số ngày công | E8: Hệ số nhiệm vụ | F8: Định mức (đ/ngày công) | G8: Thành tiền (đ) | H8: Tỷ trọng
A9: 1 | B9: Nguyễn Quốc Hội | C9: Chủ nhiệm dự án (Giám đốc dự án / PM) | D9: =SUMIF('CÔNG VIỆC'!$G:$G,$B9,'CÔNG VIỆC'!$H:$H) -> 80.5 | E9: 0.8 | F9: =E9*$E$6 -> 2024000 | G9: =D9*F9 -> 162932000 | H9: =IF($G$15=0,0,G9/$G$15) -> 0.24444866
A10: 2 | B10: Trần Tiến Thạnh | C10: Thư ký dự án (Phân tích nghiệp vụ / BA Lead) | D10: =SUMIF('CÔNG VIỆC'!$G:$G,$B10,'CÔNG VIỆC'!$H:$H) -> 84 | E10: 0.5 | F10: =E10*$E$6 -> 1265000 | G10: =D10*F10 -> 106260000 | H10: =IF($G$15=0,0,G10/$G$15) -> 0.15942304
A11: 3 | B11: Phạm Đức Hiếu | C11: Thành viên chính (Kỹ sư QA/QC & DevOps Lead) | D11: =SUMIF('CÔNG VIỆC'!$G:$G,$B11,'CÔNG VIỆC'!$H:$H) -> 114.5 | E11: 0.4 | F11: =E11*$E$6 -> 1012000 | G11: =D11*F11 -> 115874000 | H11: =IF($G$15=0,0,G11/$G$15) -> 0.17384703
A12: 4 | B12: Trần Ngọc Đức | C12: Thành viên chính (Lập trình viên Frontend & BIM 3D) | D12: =SUMIF('CÔNG VIỆC'!$G:$G,$B12,'CÔNG VIỆC'!$H:$H) -> 112 | E12: 0.4 | F12: =E12*$E$6 -> 1012000 | G12: =D12*F12 -> 113344000 | H12: =IF($G$15=0,0,G12/$G$15) -> 0.17005124
A13: 5 | B13: Nguyễn Quốc Công | C13: Thành viên (Kỹ thuật viên Tài liệu / Technical Writer) | D13: =SUMIF('CÔNG VIỆC'!$G:$G,$B13,'CÔNG VIỆC'!$H:$H) -> 110 | E13: 0.3 | F13: =E13*$E$6 -> 759000 | G13: =D13*F13 -> 83490000 | H13: =IF($G$15=0,0,G13/$G$15) -> 0.12526096
A14: 6 | B14: Nguyễn Thành An | C14: Thành viên (Tech Lead Backend & CSDL) | D14: =SUMIF('CÔNG VIỆC'!$G:$G,$B14,'CÔNG VIỆC'!$H:$H) -> 111.5 | E14: 0.3 | F14: =E14*$E$6 -> 759000 | G14: =D14*F14 -> 84628500 | H14: =IF($G$15=0,0,G14/$G$15) -> 0.12696906
B15: TỔNG CỘNG | D15: =SUM(D9:D14) -> 612.5 | F15: =IF(D15=0,0,G15/D15) -> 1088209.8 | G15: =SUM(G9:G14) -> 666528500 | H15: =IF($G$15=0,0,G15/$G$15) -> 1
A16: Bằng chữ: Sáu trăm sáu mươi sáu triệu năm trăm hai mươi tám nghìn năm trăm đồng chẵn.
A18: ĐỐI CHIẾU VỚI BẢNG PHÂN RÃ CÔNG VIỆC WBS
B19: ='CÔNG VIỆC'!H70 -> 612.5 | C19: Tổng ngày công theo WBS (EST chốt)
B20: =D15-B19 -> 0 | C20: Chênh lệch ngày công so với WBS (phải bằng 0)
B21: ='CÔNG VIỆC'!J70 -> 666528500 | C21: Tổng thành tiền
B22: =G15-B21 -> 0 | C22: Chênh lệch thành tiền (phải bằng 0)
A24: CHÚ THÍCH
A25: • Số ngày công | C25: Tự động cộng dồn từ sheet CongViec theo cột 'Người thực hiện' (hàm SUMIF), đảm bảo tính truy vết 100% với WBS.
A26: • Hệ số nhiệm vụ | C26: Quy định theo Thông tư 03/2023/TT-BKHCN và Tôn chỉ dự án: Chủ nhiệm 0,80; Thư ký 0,50; Thành viên chính 0,40; Thành viên 0,30.
A27: • Định mức/ngày công | C27: Công thức: Hệ số nhiệm vụ × Mức khoán ngày công cơ sở (ô E5 = 2.530.000 đ/ngày công chuẩn theo quy định hiện hành).
G29: Hà Nội, ngày 10 tháng 09 năm 2026
B30: GIẢNG VIÊN HƯỚNG DẪN | G30: CHỦ NHIỆM DỰ ÁN
B34: ThS. Lê Thị Hoa | G34: Nguyễn Quốc Hội

Sheet THIẾT BỊ VẬT TỰ
A1: PHỤ LỤC 2 - DỰ TOÁN KINH PHÍ VẬT TƯ, THIẾT BỊ (HẠ TẦNG CLOUD, MÁY CHỦ, BẢN QUYỀN VÀ VẬT TƯ TIÊU HAO)
A3: ĐỀ TÀI | B3: Quản lý dự án: Xây dựng hệ thống quản lý và kết nối dữ liệu dự án xây dựng
A4: MÃ SỐ | B4: CNTT20261_N10
A5: CHỦ TRÌ | B5: Nguyễn Quốc Hội
A6: Vật tư, thiết bị và dịch vụ công nghệ phục vụ đề tài - phân bổ theo 03 giai đoạn triển khai
A8: TT | B8: TÊN VẬT TƯ, THIẾT BỊ, DỊCH VỤ CÔNG NGHỆ | C8: ĐƠN VỊ TÍNH | D8: SỐ LƯỢNG | E8: ĐƠN GIÁ (đ) | F8: THÀNH TIỀN (đ) | G8: Ghi chú mục đích sử dụng
A9: I | B9: Giai đoạn 1 - Thiết lập môi trường, hạ tầng đệm & CDE (T09-T10/2026)
A10: 1 | B10: Thuê Hosting & Tên miền Domain SSL chứng chỉ cao cấp (6 tháng) | C10: Gói | D10: 1 | E10: 5000000 | F10: =D10*E10 -> 5000000 | G10: Môi trường Web và cổng xác thực HTTPS SSL chuẩn bảo mật
A11: 2 | B11: Thuê Cloud Server Dedicated GPU kết xuất mô hình BIM 3D (6 tháng) | C11: Gói | D11: 1 | E11: 35000000 | F11: =D11*E11 -> 35000000 | G11: VPS Cloud GPU chuyên dụng xử lý render và bóc tách file BIM nặng
A12: 3 | B12: Ổ cứng SSD NVMe 2TB tốc độ cao sao lưu mô hình BIM/CDE | C12: Chiếc | D12: 4 | E12: 3500000 | F12: =D12*E12 -> 14000000 | G12: Sao lưu cục bộ tốc độ cao dữ liệu mô hình BIM đa phiên bản
A13: 4 | B13: Thiết bị lưu trữ đệm tại chỗ (NAS Buffer Storage 4TB) | C13: Bộ | D13: 1 | E13: 8000000 | F13: =D13*E13 -> 8000000 | G13: Thiết bị đệm đồng bộ file CAD/BIM giữa công trường và văn phòng
A14: 5 | B14: Phụ kiện mạng chuyên dụng, cáp truyền dữ liệu sợi quang đệm | C14: Gói | D14: 1 | E14: 3000000 | F14: =D14*E14 -> 3000000 | G14: Cáp quang và đầu nối switch gigabit thử nghiệm lab CDE
A15: II | B15: Giai đoạn 2 - Phát triển, tích hợp BIM 3D & Kiểm thử (T11-T12/2026)
A16: 1 | B16: Bản quyền Autodesk Construction Cloud (ACC) API Gateway | C16: Gói | D16: 2 | E16: 30000000 | F16: =D16*E16 -> 60000000 | G16: Gateway kết nối dữ liệu mô hình Autodesk Revit & Navisworks
A17: 2 | B17: Bản quyền phần mềm kiểm thử tải cao & an toàn thông tin (JMeter Pro) | C17: Bản quyền | D17: 1 | E17: 20000000 | F17: =D17*E17 -> 20000000 | G17: Phục vụ kiểm thử Load/Stress và an toàn bảo mật OWASP Top 10
A18: 3 | B18: Thư viện đồ họa WebGL nâng cao và máy trạm kiểm thử hiện trường | C18: Hệ thống | D18: 1 | E18: 170000000 | F18: =D18*E18 -> 170000000 | G18: Engine WebGL bản quyền và máy trạm di động kiểm thử mô hình thực tế
A19: 4 | B19: Vật tư in ấn kỹ thuật, mực in, giấy in bản vẽ CAD/IFC khổ lớn A3/A4 | C19: Gói | D19: 1 | E19: 5000000 | F19: =D19*E19 -> 5000000 | G19: In ấn bản vẽ trắc đạc, hồ sơ hoàn công và biểu mẫu UAT
A20: III | B20: Giai đoạn 3 - Triển khai, Đăng ký bản quyền & Nghiệm thu (T01-T03/2027)
A21: 1 | B21: Đăng ký bản quyền SHTT giải pháp phần mềm và sở hữu trí tuệ | C21: Bộ | D21: 2 | E21: 35000000 | F21: =D21*E21 -> 70000000 | G21: Đăng ký chứng nhận bản quyền phần mềm IDD Platform tại Cục SHTT
B22: TỔNG CỘNG | F22: =SUM(F10,F11,F12,F13,F14,F16,F17,F18,F19,F21) -> 390000000 | G22: Bằng chữ: Ba trăm chín mươi triệu đồng chẵn.
A24: CHÚ THÍCH
A25: • Cơ sở lập dự toán | C25: Dự toán bao gồm Thiết bị & Máy chủ Cloud GPU (360.000.000 đ) và Vật tư đệm CDE tiêu hao (30.000.000 đ), tổng 390.000.000 đ.
A26: • Nguyên tắc | C26: Thuê hạ tầng đám mây và license bản quyền phục vụ nghiên cứu theo đúng tiến độ đề tài, kiểm soát chặt chẽ.
F28: Hà Nội, ngày 10 tháng 09 năm 2026
B29: GIẢNG VIÊN HƯỚNG DẪN | F29: CHỦ NHIỆM DỰ ÁN
B33: ThS. Lê Thị Hoa | F33: Nguyễn Quốc Hội

Sheet CHI PHÍ KHÁC
A1: PHỤ LỤC 3 - DỰ TOÁN KINH PHÍ CHI KHÁC (KHẢO SÁT, HỘI THẢO, NGHIỆM THU, VĂN PHÒNG PHẨM, QUẢN LÝ, DỰ PHÒNG)
A3: ĐỀ TÀI | B3: Quản lý dự án: Xây dựng hệ thống quản lý và kết nối dữ liệu dự án xây dựng
A4: MÃ SỐ | B4: CNTT20261_N10
A5: CHỦ TRÌ | B5: Nguyễn Quốc Hội
A6: Tổng kinh phí được duyệt theo Tôn chỉ dự án (đồng): | D6: 1128528500
A8: TT | B8: NỘI DUNG | C8: Mô tả chi tiết nội dung chi phí | D8: SỐ TIỀN (đ)
A9: I | B9: Khảo sát và đường truyền kết nối
A10: 1 | B10: Chi phí đường truyền Internet chuyên dụng, kết nối API Cloud | C10: Đường truyền cáp quang băng thông rộng 500Mbps phục vụ trao đổi file BIM và API Cloud (6 tháng × 2.000.000 đ) | D10: 12000000
A11: II | B11: Hội thảo chuyên gia, đào tạo và demo
A12: 1 | B12: Hội thảo tham vấn chuyên gia & đánh giá kiến trúc CDE | C12: Tổ chức 01 buổi hội thảo tham vấn chuyên gia công trình và phản biện giải pháp kiến trúc phần mềm | D12: 15000000
A13: 2 | B13: Đào tạo chuyển giao công nghệ & truyền thông demo sản phẩm | C13: Tổ chức 02 buổi đào tạo chuyển giao hệ thống và công tác truyền thông kết quả nghiên cứu | D13: 8000000
A14: III | B14: Nghiệm thu cơ sở & Đánh giá sản phẩm
A15: 1 | B15: Nghiệm thu cơ sở & Đánh giá của Hội đồng khoa học | C15: Thù lao Hội đồng đánh giá nghiệm thu cơ sở đề tài: Chủ tịch, thư ký, phản biện và chuyên gia | D15: 18000000
A16: IV | B16: In ấn, tài liệu, văn phòng phẩm
A17: 1 | B17: In ấn tài liệu đặc tả SRS, tài liệu HDSD, biểu mẫu dự án, VPP | C17: 06 bộ hồ sơ dự án đóng quyển (Thuyết minh, SRS, SAD, QLDA, BCTC) và văn phòng phẩm phục vụ | D17: 6000000
A18: V | B18: Chi phí quản lý và quỹ dự phòng
A19: 1 | B19: Kinh phí quản lý của cơ quan chủ trì | C19: Thư ký hành chính & quản lý điều phối hồ sơ đề tài theo quy chế (6 tháng × 500.000 đ) | D19: 3000000
A20: 2 | B20: Quỹ dự phòng (Contingency Reserve) | C20: Tự cân đối: Tổng kinh phí được duyệt trừ Công lao động, Vật tư thiết bị và các khoản Chi khác đã liệt kê | D20: =$D$6-'CÔNG LAO ĐỘNG'!$G$15-'THIẾT BỊ VẬT TỰ'!$F$22-(D10+D12+D13+D15+D17+D19) -> 10000000
B21: TỔNG CỘNG | D21: =SUM(D10,D12,D13,D15,D17,D19,D20) -> 72000000
A22: Bằng chữ: Bảy mươi hai triệu đồng chẵn.
A24: CHÚ THÍCH
A25: • Cơ sở lập dự toán | C25: Đường truyền Internet Cloud 12tr; Hội thảo & đào tạo demo 23tr; Nghiệm thu cơ sở 18tr; In ấn tài liệu VPP 6tr; Quản lý cơ quan 3tr; Quỹ dự phòng 10tr.
A26: • Dòng Quỹ dự phòng | C26: Là công thức tự cân đối để Tổng dự toán luôn bằng đúng Tổng kinh phí được duyệt (ô D5); khi điều chỉnh bất kỳ khoản mục nào, Quỹ dự phòng tự điều chỉnh tương ứng.
D28: Hà Nội, ngày 10 tháng 09 năm 2026
B29: GIẢNG VIÊN HƯỚNG DẪN | D29: CHỦ NHIỆM DỰ ÁN
B33: ThS. Lê Thị Hoa | D33: Nguyễn Quốc Hội

Sheet KẾ HOẠCH THANH TOÁN
A1: PHỤ LỤC 4 - DỰ TOÁN KINH PHÍ KẾ HOẠCH THANH TOÁN VÀ DÒNG TIỀN DỰ ÁN
A3: ĐỀ TÀI | B3: Quản lý dự án: Xây dựng hệ thống quản lý và kết nối dữ liệu dự án xây dựng
A4: MÃ SỐ | B4: CNTT20261_N10
A5: CHỦ TRÌ | B5: Nguyễn Quốc Hội
A6: Giá trị hợp đồng với Chủ đầu tư (đồng): | D6: ='CHI PHÍ KHÁC'!$D$6 -> 1128528500
A7: Số ngày làm việc từ khi nghiệm thu đến khi nhận tiền: | D7: 7
A9: I. KẾ HOẠCH THANH TOÁN THEO CỘT MỐC NGHIỆM THU
A10: TT | B10: Đợt thanh toán | C10: Cột mốc nghiệm thu | D10: Ngày cột mốc | E10: Điều kiện thanh toán (hồ sơ kèm theo) | F10: Tỷ lệ (%) | G10: Số tiền (đ) | H10: Ngày nhận tiền dự kiến | I10: Lũy kế thu (đ) | J10: Ghi chú mục đích
A11: 1 | B11: Đợt 1 - Tạm ứng | C11: M01 - Khởi động & Phê duyệt Project Charter | D11: 46276 | E11: Hợp đồng đã ký; Biên bản phê duyệt Project Charter & Dự thảo SRS; Đề nghị tạm ứng | F11: 0.2 | G11: =ROUND($D$6*F11,0) -> 225705700 | H11: =WORKDAY(D11,$D$7) -> 46287 | I11: =SUM($G$11:G11) -> 225705700 | J11: Khởi động dự án, chi trả giai đoạn Khảo sát yêu cầu và thiết lập hạ tầng CDE
A12: 2 | B12: Đợt 2 | C12: M02 - Nghiệm thu Khảo sát SRS & Baseline | D12: 46304 | E12: Tài liệu SRS v1.0 và Kế hoạch quản trị dự án tổng thể được Ban Chỉ đạo phê duyệt | F12: 0.15 | G12: =ROUND($D$6*F12,0) -> 169279275 | H12: =WORKDAY(D12,$D$7) -> 46315 | I12: =SUM($G$11:G12) -> 394984975 | J12: Bù chi giai đoạn Khảo sát công nghệ, thiết lập môi trường và hội thảo chuyên gia
A13: 3 | B13: Đợt 3 | C13: M03 - Ký xác nhận Thiết kế SAD & Prototype UI/UX | D13: 46332 | E13: Báo cáo Phân tích thiết kế hệ thống (SAD, UML) và Prototype Figma hoàn chỉnh | F13: 0.15 | G13: =ROUND($D$6*F13,0) -> 169279275 | H13: =WORKDAY(D13,$D$7) -> 46343 | I13: =SUM($G$11:G13) -> 564264250 | J13: Bù chi giai đoạn Thiết kế UI/UX và bản quyền Autodesk ACC API Gateway
A14: 4 | B14: Đợt 4 | C14: M04 - Nghiệm thu hoàn thiện Core Backend & BIM 3D | D14: 46367 | E14: Module WebGL Three.js, RESTful API Backend, tài liệu HDSD sơ bộ được nghiệm thu | F14: 0.25 | G14: =ROUND($D$6*F14,0) -> 282132125 | H14: =WORKDAY(D14,$D$7) -> 46378 | I14: =SUM($G$11:G14) -> 846396375 | J14: Đợt giải ngân lớn nhất, đón trước giai đoạn hoàn thiện Core Dev và kiểm thử tải
A15: 5 | B15: Đợt 5 | C15: M05 - Nghiệm thu Kiểm thử E2E & Triển khai Staging | D15: 46409 | E15: Biên bản nghiệm thu Test E2E, hệ thống Staging chạy ổn định không còn bug nghiêm trọng | F15: 0.2 | G15: =ROUND($D$6*F15,0) -> 225705700 | H15: =WORKDAY(D15,$D$7) -> 46420 | I15: =SUM($G$11:G15) -> 1072102075 | J15: Bù chi giai đoạn Kiểm thử toàn diện, tối ưu hiệu năng và nghiệm thu cơ sở
A16: 6 | B16: Đợt 6 - Quyết toán | C16: M06 - Triển khai Cloud & Nghiệm thu Bảo vệ Đề tài | D16: 46444 | E16: Biên bản nghiệm thu chính thức của Hội đồng; Hồ sơ quyết toán; Biên bản đóng đề tài | F16: 0.05 | G16: =ROUND($D$6*F16,0) -> 56426425 | H16: =WORKDAY(D16,$D$7) -> 46455 | I16: =SUM($G$11:G16) -> 1128528500 | J16: Khoản giữ lại 5% thanh toán khi hoàn tất bảo vệ và đóng hợp đồng đề tài
B17: TỔNG CỘNG | F17: =SUM(F11:F16) -> 1 | G17: =SUM(G11:G16) -> 1128528500 | J17: =IF(ROUND(F17,6)=1,"Đủ 100% giá trị hợp đồng","Tổng tỷ lệ phải bằng 100%") -> Đủ 100% giá trị hợp đồng
A19: II. DÒNG TIỀN DỰ KIẾN THEO THÁNG (CHI THEO COST BASELINE, THU THEO KẾ HOẠCH THANH TOÁN)
A20: Tháng | B20: Ngày cuối tháng | C20: Chi công lao động (đ) | D20: Chi vật tư, thiết bị (đ) | E20: Chi khác, không gồm dự phòng (đ) | F20: Tổng chi trong tháng (đ) | G20: Lũy kế chi (đ) | H20: Thu trong tháng (đ) | I20: Lũy kế thu (đ) | J20: Chênh lệch lũy kế thu - chi (đ)
A21: T09/2026 | B21: =EOMONTH(DATE(2026,9,1),0) -> 46295 | C21: 55000000 | D21: 19000000 | E21: 5000000 | F21: =SUM(C21:E21) -> 79000000 | G21: =SUM($F$21:F21) -> 79000000 | H21: =SUMIFS($G$11:$G$16,$H$11:$H$16,">"&EOMONTH(B21,-1),$H$11:$H$16,"<="&B21) -> 225705700 | I21: =SUM($H$21:H21) -> 225705700 | J21: =I21-G21 -> 146705700
A22: T10/2026 | B22: =EOMONTH(B21,1) -> 46326 | C22: 85000000 | D22: 46000000 | E22: 17000000 | F22: =SUM(C22:E22) -> 148000000 | G22: =SUM($F$21:F22) -> 227000000 | H22: =SUMIFS($G$11:$G$16,$H$11:$H$16,">"&EOMONTH(B22,-1),$H$11:$H$16,"<="&B22) -> 169279275 | I22: =SUM($H$21:H22) -> 394984975 | J22: =I22-G22 -> 167984975
A23: T11/2026 | B23: =EOMONTH(B22,1) -> 46356 | C23: 95000000 | D23: 40000000 | E23: 4000000 | F23: =SUM(C23:E23) -> 139000000 | G23: =SUM($F$21:F23) -> 366000000 | H23: =SUMIFS($G$11:$G$16,$H$11:$H$16,">"&EOMONTH(B23,-1),$H$11:$H$16,"<="&B23) -> 169279275 | I23: =SUM($H$21:H23) -> 564264250 | J23: =I23-G23 -> 198264250
A24: T12/2026 | B24: =EOMONTH(B23,1) -> 46387 | C24: 140000000 | D24: 135000000 | E24: 6000000 | F24: =SUM(C24:E24) -> 281000000 | G24: =SUM($F$21:F24) -> 647000000 | H24: =SUMIFS($G$11:$G$16,$H$11:$H$16,">"&EOMONTH(B24,-1),$H$11:$H$16,"<="&B24) -> 282132125 | I24: =SUM($H$21:H24) -> 846396375 | J24: =I24-G24 -> 199396375
A25: T01/2027 | B25: =EOMONTH(B24,1) -> 46418 | C25: 120000000 | D25: 40000000 | E25: 4000000 | F25: =SUM(C25:E25) -> 164000000 | G25: =SUM($F$21:F25) -> 811000000 | H25: =SUMIFS($G$11:$G$16,$H$11:$H$16,">"&EOMONTH(B25,-1),$H$11:$H$16,"<="&B25) -> 0 | I25: =SUM($H$21:H25) -> 846396375 | J25: =I25-G25 -> 35396375
A26: T02/2027 | B26: =EOMONTH(B25,1) -> 46446 | C26: 110000000 | D26: 70000000 | E26: 22000000 | F26: =SUM(C26:E26) -> 202000000 | G26: =SUM($F$21:F26) -> 1013000000 | H26: =SUMIFS($G$11:$G$16,$H$11:$H$16,">"&EOMONTH(B26,-1),$H$11:$H$16,"<="&B26) -> 225705700 | I26: =SUM($H$21:H26) -> 1072102075 | J26: =I26-G26 -> 59102075
A27: T03/2027 | B27: =EOMONTH(B26,1) -> 46477 | C27: 61528500 | D27: 40000000 | E27: 4000000 | F27: =SUM(C27:E27) -> 105528500 | G27: =SUM($F$21:F27) -> 1118528500 | H27: =SUMIFS($G$11:$G$16,$H$11:$H$16,">"&EOMONTH(B27,-1),$H$11:$H$16,"<="&B27) -> 56426425 | I27: =SUM($H$21:H27) -> 1128528500 | J27: =I27-G27 -> 10000000
A28: TỔNG CỘNG | C28: =SUM(C21:C27) -> 666528500 | D28: =SUM(D21:D27) -> 390000000 | E28: =SUM(E21:E27) -> 62000000 | F28: =SUM(F21:F27) -> 1118528500 | G28: =G27 -> 1118528500 | H28: =SUM(H21:H27) -> 1128528500 | I28: =I27 -> 1128528500 | J28: =J27 -> 10000000
A30: III. ĐỐI CHIẾU
A31: TT | B31: Chỉ tiêu kiểm soát dòng tiền | E31: Giá trị (đ) | F31: Ghi chú kiểm soát
A32: 1 | B32: Chênh lệch chi công lao động so với sheet CongLaoDong | E32: =C28-'CÔNG LAO ĐỘNG'!$G$15 -> 0 | F32: Phải bằng 0: Chi công lao động khớp 100% với bảng khoán chi
A33: 2 | B33: Chênh lệch chi vật tư, thiết bị so với sheet Thiết bị vật tư | E33: =D28-'THIẾT BỊ VẬT TỰ'!$F$22 -> 0 | F33: Phải bằng 0: Chi thiết bị vật tư khớp 100% với phụ lục thiết bị
A34: 3 | B34: Chênh lệch chi khác so với sheet Chi khác (không gồm dự phòng) | E34: =E28-('CHI PHÍ KHÁC'!$D$21-'CHI PHÍ KHÁC'!$D$20) -> 0 | F34: Phải bằng 0: Chi khác thực tế khớp 100% với phụ lục chi khác
A35: 4 | B35: Chênh lệch tổng thu so với giá trị hợp đồng | E35: =H28-$D$6 -> 0 | F35: Phải bằng 0: Tổng thu qua 6 đợt đủ 100% giá trị hợp đồng được duyệt
A36: 5 | B36: Chênh lệch lũy kế cuối dự án so với Quỹ dự phòng | E36: =J27-'CHI PHÍ KHÁC'!$D$20 -> 0 | F36: Phải bằng 0: Phần dư cuối dự án đúng bằng khoản Quỹ dự phòng chưa sử dụng
A37: 6 | B37: Số tháng có chênh lệch lũy kế thu - chi âm | E37: =COUNTIF(J21:J27,"<0") -> 0 | F37: Phải bằng 0: Dự án đảm bảo không thiếu hụt dòng tiền tại mọi thời điểm cuối tháng
A38: 7 | B38: Chênh lệch lũy kế thu - chi thấp nhất trong kỳ | E38: =MIN(J21:J27) -> 10000000 | F38: Biên an toàn dòng tiền tối thiểu; đạt dương tại mọi thời điểm trong 07 tháng
A40: CHÚ THÍCH
A41: • Ngày cột mốc | B41: Theo danh mục 6 cột mốc chiến lược M01-M06 tại Kế hoạch quản lý tiến độ MS Project: M01 11/09/2026; M02 09/10/2026; M03 06/11/2026; M04 11/12/2026; M05 22/01/2027; M06 26/02/2027.
A42: • Ngày nhận tiền | B42: Công thức WORKDAY(Ngày cột mốc, ô D6), loại trừ thứ Bảy, Chủ nhật và tính đúng thời hạn thanh toán 07 ngày làm việc.
A43: • Thu trong tháng | B43: Công thức SUMIFS cộng tự động các đợt giải ngân có Ngày nhận tiền rơi vào tháng tương ứng.
A44: • Phân bổ chi theo tháng | B44: Công lao động và thiết bị vật tư được phân bổ theo tiến độ thực tế triển khai 06 giai đoạn; số lẻ làm tròn được dồn vào tháng 03/2027.
A45: • Giả định dòng chi | B45: Chi phí được thanh toán vào cuối tháng phát sinh; khoản Quỹ dự phòng không đưa vào dòng chi kế hoạch và chỉ sử dụng khi kích hoạt quy trình quản lý rủi ro.
...
